Workbook

Sheet Tổng hợp
B1: TỔNG HỢP ĐỀ XUẤT PHÂN CÔNG NHIỆM VỤ
B2: NĂM HỌC: 2026 - 2027
A4: TỔ | B4: STT | C4: GIÁO VIÊN | D4: CN | E4: KHỐI 12 | K4: KHỐI 11 | P4: KHỐI 10 | U4: SỐ TIẾT DẠY | V4: SỐ TIẾT CHỦ NHIỆM | W4: CHỨC VỤ | Y4: SỐ TIẾT CHÍNH QUYỀN - ĐOÀN THỂ | Z4: TỔNG SỐ TIẾT / TUẦN | AA4: SỐ TIẾT PHỤ TRỘI THEO / TUẦN | AB4: DẠY HSG, MTCT, OLYMPIC, NCKH | AE4: PHỤ ĐẠO | AH4: QUY ĐỔI CHUYÊN MÔN KHÁC | AK4: TỔNG SỐ TIẾT PHỤ TRỘI | AL4: HSG OLYMPIC NCKH MTCT | AM4: PHỤ ĐẠO | AN4: THAO GIẢNG GVG GVCNG | AO4: RA ĐỀ KIỂM TRA HỌC KỲ 1 | AP4: RA ĐỀ KIỂM TRA HỌC KỲ 2 | AQ4: LẬP KHGD | AR4: XÂY DỰNG KẾ HOẠCH NGOẠI KHÓA | AS4: PHỤ TRÁCH HOẠT ĐỘNG CLB | AT4: THỰC HIỆN HỌC LIỆU SỐ | AU4: THỰC HIỆN NHIỆM VỤ KHÁC | AV4: GHI CHÚ | AW4: TIẾT TNHN THỰC TẾ
E5: SL | F5: CN | G5: CĐ | H5: ÔN TN | I5: TNHN | J5: GDĐP | K5: SL | L5: CN | M5: CĐ | N5: TNHN | O5: GDĐP | P5: SL | Q5: CN | R5: CĐ | S5: TNHN | T5: GDĐP | W5: CHÍNH QUYỀN | X5: ĐOÀN THỂ | AB5: SỐ TIẾT/TUẦN | AC5: SỐ TUẦN | AD5: TỔNG SỐ | AE5: SỐ TIẾT/TUẦN | AF5: SỐ TUẦN | AG5: TỔNG SỐ | AH5: SỐ TIẾT/TUẦN | AI5: SỐ TUẦN | AJ5: TỔNG SỐ | AW5: K12 | AX5: K11 | AY5: K10
A6: TIẾNG ANH | B6: 1 | C6: NGUYỄN VĂN HÙNG | E6: 3 | H6: 2 | P6: 2 | U6: =E6*'Phân tiết'!$M$7+G6*('Phân tiết'!$M$21/3)+H6*'Phân tiết'!$L$26+AW6+J6*'Phân tiết'!$M$20+K6*'Phân tiết'!$I$7+M6*('Phân tiết'!$I$21/3)+AX6+O6*'Phân tiết'!$I$20+P6*'Phân tiết'!$E$7+R6*('Phân tiết'!$E$21/3)+AY6+T6*'Phân tiết'!$E$20 -> 19 | V6: =F6*4+L6*4+Q6*4 -> 0 | W6: TTCM | Y6: 3 | Z6: =SUM(U6:Y6) -> 22 | AA6: =Z6-17 -> 5 | AD6: =AB6*AC6*1.5 -> 0 | AG6: =AE6*AF6*1.5 -> 0 | AJ6: =AH6*AI6 -> 0 | AK6: =AA6*33+AD6+AG6+AJ6 -> 165 | AO6: X | AP6: X | AQ6: X | AR6: X | AS6: X | AT6: X | AW6: =IF(I6="",0,IF(MAP_TNHN!B6="",I6*3,I6*3-2*(IF(ISNUMBER(SEARCH(MAP_TNHN!B6&" (1 tiết)",'PL12'!$S$5)),1,0)+IF(ISNUMBER(SEARCH(MAP_TNHN!B6&" (1 tiết)",'PL12'!$S$6)),1,0)+IF(ISNUMBER(SEARCH(MAP_TNHN!B6&" (1 tiết)",'PL12'!$S$7)),1,0)+IF(ISNUMBER(SEARCH(MAP_TNHN!B6&" (1 tiết)",'PL12'!$S$8)),1,0)+IF(ISNUMBER(SEARCH(MAP_TNHN!B6&" (1 tiết)",'PL12'!$S$9)),1,0)+IF(ISNUMBER(SEARCH(MAP_TNHN!B6&" (1 tiết)",'PL12'!$S$10)),1,0)+IF(ISNUMBER(SEARCH(MAP_TNHN!B6&" (1 tiết)",'PL12'!$S$11)),1,0)+IF(ISNUMBER(SEARCH(MAP_TNHN!B6&" (1 tiết)",'PL12'!$S$12)),1,0)+IF(ISNUMBER(SEARCH(MAP_TNHN!B6&" (1 tiết)",'PL12'!$S$13)),1,0)+IF(ISNUMBER(SEARCH(MAP_TNHN!B6&" (1 tiết)",'PL12'!$S$14)),1,0)+IF(ISNUMBER(SEARCH(MAP_TNHN!B6&" (1 tiết)",'PL12'!$S$15)),1,0)+IF(ISNUMBER(SEARCH(MAP_TNHN!B6&" (1 tiết)",'PL12'!$S$16)),1,0)+IF(ISNUMBER(SEARCH(MAP_TNHN!B6&" (1 tiết)",'PL12'!$S$17)),1,0)+IF(ISNUMBER(SEARCH(MAP_TNHN!B6&" (1 tiết)",'PL12'!$S$18)),1,0)+IF(ISNUMBER(SEARCH(MAP_TNHN!B6&" (1 tiết)",'PL12'!$S$19)),1,0))-(IF(ISNUMBER(SEARCH(MAP_TNHN!B6&" (2 tiết)",'PL12'!$S$5)),1,0)+IF(ISNUMBER(SEARCH(MAP_TNHN!B6&" (2 tiết)",'PL12'!$S$6)),1,0)+IF(ISNUMBER(SEARCH(MAP_TNHN!B6&" (2 tiết)",'PL12'!$S$7)),1,0)+IF(ISNUMBER(SEARCH(MAP_TNHN!B6&" (2 tiết)",'PL12'!$S$8)),1,0)+IF(ISNUMBER(SEARCH(MAP_TNHN!B6&" (2 tiết)",'PL12'!$S$9)),1,0)+IF(ISNUMBER(SEARCH(MAP_TNHN!B6&" (2 tiết)",'PL12'!$S$10)),1,0)+IF(ISNUMBER(SEARCH(MAP_TNHN!B6&" (2 tiết)",'PL12'!$S$11)),1,0)+IF(ISNUMBER(SEARCH(MAP_TNHN!B6&" (2 tiết)",'PL12'!$S$12)),1,0)+IF(ISNUMBER(SEARCH(MAP_TNHN!B6&" (2 tiết)",'PL12'!$S$13)),1,0)+IF(ISNUMBER(SEARCH(MAP_TNHN!B6&" (2 tiết)",'PL12'!$S$14)),1,0)+IF(ISNUMBER(SEARCH(MAP_TNHN!B6&" (2 tiết)",'PL12'!$S$15)),1,0)+IF(ISNUMBER(SEARCH(MAP_TNHN!B6&" (2 tiết)",'PL12'!$S$16)),1,0)+IF(ISNUMBER(SEARCH(MAP_TNHN!B6&" (2 tiết)",'PL12'!$S$17)),1,0)+IF(ISNUMBER(SEARCH(MAP_TNHN!B6&" (2 tiết)",'PL12'!$S$18)),1,0)+IF(ISNUMBER(SEARCH(MAP_TNHN!B6&" (2 tiết)",'PL12'!$S$19)),1,0)))) -> 0 | AX6: =IF(N6="",0,IF(MAP_TNHN!C6="",N6*3,N6*3-2*(IF(ISNUMBER(SEARCH(MAP_TNHN!C6&" (1 tiết)",'PL11'!$S$5)),1,0)+IF(ISNUMBER(SEARCH(MAP_TNHN!C6&" (1 tiết)",'PL11'!$S$6)),1,0)+IF(ISNUMBER(SEARCH(MAP_TNHN!C6&" (1 tiết)",'PL11'!$S$7)),1,0)+IF(ISNUMBER(SEARCH(MAP_TNHN!C6&" (1 tiết)",'PL11'!$S$8)),1,0)+IF(ISNUMBER(SEARCH(MAP_TNHN!C6&" (1 tiết)",'PL11'!$S$9)),1,0)+IF(ISNUMBER(SEARCH(MAP_TNHN!C6&" (1 tiết)",'PL11'!$S$10)),1,0)+IF(ISNUMBER(SEARCH(MAP_TNHN!C6&" (1 tiết)",'PL11'!$S$11)),1,0)+IF(ISNUMBER(SEARCH(MAP_TNHN!C6&" (1 tiết)",'PL11'!$S$12)),1,0)+IF(ISNUMBER(SEARCH(MAP_TNHN!C6&" (1 tiết)",'PL11'!$S$13)),1,0)+IF(ISNUMBER(SEARCH(MAP_TNHN!C6&" (1 tiết)",'PL11'!$S$14)),1,0)+IF(ISNUMBER(SEARCH(MAP_TNHN!C6&" (1 tiết)",'PL11'!$S$15)),1,0)+IF(ISNUMBER(SEARCH(MAP_TNHN!C6&" (1 tiết)",'PL11'!$S$16)),1,0)+IF(ISNUMBER(SEARCH(MAP_TNHN!C6&" (1 tiết)",'PL11'!$S$17)),1,0)+IF(ISNUMBER(SEARCH(MAP_TNHN!C6&" (1 tiết)",'PL11'!$S$18)),1,0))-(IF(ISNUMBER(SEARCH(MAP_TNHN!C6&" (2 tiết)",'PL11'!$S$5)),1,0)+IF(ISNUMBER(SEARCH(MAP_TNHN!C6&" (2 tiết)",'PL11'!$S$6)),1,0)+IF(ISNUMBER(SEARCH(MAP_TNHN!C6&" (2 tiết)",'PL11'!$S$7)),1,0)+IF(ISNUMBER(SEARCH(MAP_TNHN!C6&" (2 tiết)",'PL11'!$S$8)),1,0)+IF(ISNUMBER(SEARCH(MAP_TNHN!C6&" (2 tiết)",'PL11'!$S$9)),1,0)+IF(ISNUMBER(SEARCH(MAP_TNHN!C6&" (2 tiết)",'PL11'!$S$10)),1,0)+IF(ISNUMBER(SEARCH(MAP_TNHN!C6&" (2 tiết)",'PL11'!$S$11)),1,0)+IF(ISNUMBER(SEARCH(MAP_TNHN!C6&" (2 tiết)",'PL11'!$S$12)),1,0)+IF(ISNUMBER(SEARCH(MAP_TNHN!C6&" (2 tiết)",'PL11'!$S$13)),1,0)+IF(ISNUMBER(SEARCH(MAP_TNHN!C6&" (2 tiết)",'PL11'!$S$14)),1,0)+IF(ISNUMBER(SEARCH(MAP_TNHN!C6&" (2 tiết)",'PL11'!$S$15)),1,0)+IF(ISNUMBER(SEARCH(MAP_TNHN!C6&" (2 tiết)",'PL11'!$S$16)),1,0)+IF(ISNUMBER(SEARCH(MAP_TNHN!C6&" (2 tiết)",'PL11'!$S$17)),1,0)+IF(ISNUMBER(SEARCH(MAP_TNHN!C6&" (2 tiết)",'PL11'!$S$18)),1,0)))) -> 0 | AY6: =IF(S6="",0,IF(MAP_TNHN!D6="",S6*3,S6*3-2*(IF(ISNUMBER(SEARCH(MAP_TNHN!D6&" (1 tiết)",'PL10'!$S$5)),1,0)+IF(ISNUMBER(SEARCH(MAP_TNHN!D6&" (1 tiết)",'PL10'!$S$6)),1,0)+IF(ISNUMBER(SEARCH(MAP_TNHN!D6&" (1 tiết)",'PL10'!$S$7)),1,0)+IF(ISNUMBER(SEARCH(MAP_TNHN!D6&" (1 tiết)",'PL10'!$S$8)),1,0)+IF(ISNUMBER(SEARCH(MAP_TNHN!D6&" (1 tiết)",'PL10'!$S$9)),1,0)+IF(ISNUMBER(SEARCH(MAP_TNHN!D6&" (1 tiết)",'PL10'!$S$10)),1,0)+IF(ISNUMBER(SEARCH(MAP_TNHN!D6&" (1 tiết)",'PL10'!$S$11)),1,0)+IF(ISNUMBER(SEARCH(MAP_TNHN!D6&" (1 tiết)",'PL10'!$S$12)),1,0)+IF(ISNUMBER(SEARCH(MAP_TNHN!D6&" (1 tiết)",'PL10'!$S$13)),1,0)+IF(ISNUMBER(SEARCH(MAP_TNHN!D6&" (1 tiết)",'PL10'!$S$14)),1,0)+IF(ISNUMBER(SEARCH(MAP_TNHN!D6&" (1 tiết)",'PL10'!$S$15)),1,0)+IF(ISNUMBER(SEARCH(MAP_TNHN!D6&" (1 tiết)",'PL10'!$S$16)),1,0)+IF(ISNUMBER(SEARCH(MAP_TNHN!D6&" (1 tiết)",'PL10'!$S$17)),1,0)+IF(ISNUMBER(SEARCH(MAP_TNHN!D6&" (1 tiết)",'PL10'!$S$18)),1,0)+IF(ISNUMBER(SEARCH(MAP_TNHN!D6&" (1 tiết)",'PL10'!$S$19)),1,0)+IF(ISNUMBER(SEARCH(MAP_TNHN!D6&" (1 tiết)",'PL10'!$S$20)),1,0)+IF(ISNUMBER(SEARCH(MAP_TNHN!D6&" (1 tiết)",'PL10'!$S$21)),1,0)+IF(ISNUMBER(SEARCH(MAP_TNHN!D6&" (1 tiết)",'PL10'!$S$22)),1,0)+IF(ISNUMBER(SEARCH(MAP_TNHN!D6&" (1 tiết)",'PL10'!$S$23)),1,0)+IF(ISNUMBER(SEARCH(MAP_TNHN!D6&" (1 tiết)",'PL10'!$S$24)),1,0)+IF(ISNUMBER(SEARCH(MAP_TNHN!D6&" (1 tiết)",'PL10'!$S$25)),1,0))-(IF(ISNUMBER(SEARCH(MAP_TNHN!D6&" (2 tiết)",'PL10'!$S$5)),1,0)+IF(ISNUMBER(SEARCH(MAP_TNHN!D6&" (2 tiết)",'PL10'!$S$6)),1,0)+IF(ISNUMBER(SEARCH(MAP_TNHN!D6&" (2 tiết)",'PL10'!$S$7)),1,0)+IF(ISNUMBER(SEARCH(MAP_TNHN!D6&" (2 tiết)",'PL10'!$S$8)),1,0)+IF(ISNUMBER(SEARCH(MAP_TNHN!D6&" (2 tiết)",'PL10'!$S$9)),1,0)+IF(ISNUMBER(SEARCH(MAP_TNHN!D6&" (2 tiết)",'PL10'!$S$10)),1,0)+IF(ISNUMBER(SEARCH(MAP_TNHN!D6&" (2 tiết)",'PL10'!$S$11)),1,0)+IF(ISNUMBER(SEARCH(MAP_TNHN!D6&" (2 tiết)",'PL10'!$S$12)),1,0)+IF(ISNUMBER(SEARCH(MAP_TNHN!D6&" (2 tiết)",'PL10'!$S$13)),1,0)+IF(ISNUMBER(SEARCH(MAP_TNHN!D6&" (2 tiết)",'PL10'!$S$14)),1,0)+IF(ISNUMBER(SEARCH(MAP_TNHN!D6&" (2 tiết)",'PL10'!$S$15)),1,0)+IF(ISNUMBER(SEARCH(MAP_TNHN!D6&" (2 tiết)",'PL10'!$S$16)),1,0)+IF(ISNUMBER(SEARCH(MAP_TNHN!D6&" (2 tiết)",'PL10'!$S$17)),1,0)+IF(ISNUMBER(SEARCH(MAP_TNHN!D6&" (2 tiết)",'PL10'!$S$18)),1,0)+IF(ISNUMBER(SEARCH(MAP_TNHN!D6&" (2 tiết)",'PL10'!$S$19)),1,0)+IF(ISNUMBER(SEARCH(MAP_TNHN!D6&" (2 tiết)",'PL10'!$S$20)),1,0)+IF(ISNUMBER(SEARCH(MAP_TNHN!D6&" (2 tiết)",'PL10'!$S$21)),1,0)+IF(ISNUMBER(SEARCH(MAP_TNHN!D6&" (2 tiết)",'PL10'!$S$22)),1,0)+IF(ISNUMBER(SEARCH(MAP_TNHN!D6&" (2 tiết)",'PL10'!$S$23)),1,0)+IF(ISNUMBER(SEARCH(MAP_TNHN!D6&" (2 tiết)",'PL10'!$S$24)),1,0)+IF(ISNUMBER(SEARCH(MAP_TNHN!D6&" (2 tiết)",'PL10'!$S$25)),1,0)))) -> 0
B7: 2 | C7: NGUYỄN MINH THANH TÙNG | D7: 10 | E7: 2 | H7: 1 | P7: 3 | Q7: 1 | S7: 1 | U7: =E7*'Phân tiết'!$M$7+G7*('Phân tiết'!$M$21/3)+H7*'Phân tiết'!$L$26+AW7+J7*'Phân tiết'!$M$20+K7*'Phân tiết'!$I$7+M7*('Phân tiết'!$I$21/3)+AX7+O7*'Phân tiết'!$I$20+P7*'Phân tiết'!$E$7+R7*('Phân tiết'!$E$21/3)+AY7+T7*'Phân tiết'!$E$20 -> 18 | V7: =F7*4+L7*4+Q7*4 -> 4 | Z7: =SUM(U7:Y7) -> 22 | AA7: =Z7-17 -> 5 | AB7: 2 | AC7: 8 | AD7: =AB7*AC7*1.5 -> 24 | AG7: =AE7*AF7*1.5 -> 0 | AJ7: =AH7*AI7 -> 0 | AK7: =AA7*33+AD7+AG7+AJ7 -> 189 | AL7: Olympic 11 | AN7: X | AO7: X | AP7: X | AT7: X | AW7: =IF(I7="",0,IF(MAP_TNHN!B7="",I7*3,I7*3-2*(IF(ISNUMBER(SEARCH(MAP_TNHN!B7&" (1 tiết)",'PL12'!$S$5)),1,0)+IF(ISNUMBER(SEARCH(MAP_TNHN!B7&" (1 tiết)",'PL12'!$S$6)),1,0)+IF(ISNUMBER(SEARCH(MAP_TNHN!B7&" (1 tiết)",'PL12'!$S$7)),1,0)+IF(ISNUMBER(SEARCH(MAP_TNHN!B7&" (1 tiết)",'PL12'!$S$8)),1,0)+IF(ISNUMBER(SEARCH(MAP_TNHN!B7&" (1 tiết)",'PL12'!$S$9)),1,0)+IF(ISNUMBER(SEARCH(MAP_TNHN!B7&" (1 tiết)",'PL12'!$S$10)),1,0)+IF(ISNUMBER(SEARCH(MAP_TNHN!B7&" (1 tiết)",'PL12'!$S$11)),1,0)+IF(ISNUMBER(SEARCH(MAP_TNHN!B7&" (1 tiết)",'PL12'!$S$12)),1,0)+IF(ISNUMBER(SEARCH(MAP_TNHN!B7&" (1 tiết)",'PL12'!$S$13)),1,0)+IF(ISNUMBER(SEARCH(MAP_TNHN!B7&" (1 tiết)",'PL12'!$S$14)),1,0)+IF(ISNUMBER(SEARCH(MAP_TNHN!B7&" (1 tiết)",'PL12'!$S$15)),1,0)+IF(ISNUMBER(SEARCH(MAP_TNHN!B7&" (1 tiết)",'PL12'!$S$16)),1,0)+IF(ISNUMBER(SEARCH(MAP_TNHN!B7&" (1 tiết)",'PL12'!$S$17)),1,0)+IF(ISNUMBER(SEARCH(MAP_TNHN!B7&" (1 tiết)",'PL12'!$S$18)),1,0)+IF(ISNUMBER(SEARCH(MAP_TNHN!B7&" (1 tiết)",'PL12'!$S$19)),1,0))-(IF(ISNUMBER(SEARCH(MAP_TNHN!B7&" (2 tiết)",'PL12'!$S$5)),1,0)+IF(ISNUMBER(SEARCH(MAP_TNHN!B7&" (2 tiết)",'PL12'!$S$6)),1,0)+IF(ISNUMBER(SEARCH(MAP_TNHN!B7&" (2 tiết)",'PL12'!$S$7)),1,0)+IF(ISNUMBER(SEARCH(MAP_TNHN!B7&" (2 tiết)",'PL12'!$S$8)),1,0)+IF(ISNUMBER(SEARCH(MAP_TNHN!B7&" (2 tiết)",'PL12'!$S$9)),1,0)+IF(ISNUMBER(SEARCH(MAP_TNHN!B7&" (2 tiết)",'PL12'!$S$10)),1,0)+IF(ISNUMBER(SEARCH(MAP_TNHN!B7&" (2 tiết)",'PL12'!$S$11)),1,0)+IF(ISNUMBER(SEARCH(MAP_TNHN!B7&" (2 tiết)",'PL12'!$S$12)),1,0)+IF(ISNUMBER(SEARCH(MAP_TNHN!B7&" (2 tiết)",'PL12'!$S$13)),1,0)+IF(ISNUMBER(SEARCH(MAP_TNHN!B7&" (2 tiết)",'PL12'!$S$14)),1,0)+IF(ISNUMBER(SEARCH(MAP_TNHN!B7&" (2 tiết)",'PL12'!$S$15)),1,0)+IF(ISNUMBER(SEARCH(MAP_TNHN!B7&" (2 tiết)",'PL12'!$S$16)),1,0)+IF(ISNUMBER(SEARCH(MAP_TNHN!B7&" (2 tiết)",'PL12'!$S$17)),1,0)+IF(ISNUMBER(SEARCH(MAP_TNHN!B7&" (2 tiết)",'PL12'!$S$18)),1,0)+IF(ISNUMBER(SEARCH(MAP_TNHN!B7&" (2 tiết)",'PL12'!$S$19)),1,0)))) -> 0 | AX7: =IF(N7="",0,IF(MAP_TNHN!C7="",N7*3,N7*3-2*(IF(ISNUMBER(SEARCH(MAP_TNHN!C7&" (1 tiết)",'PL11'!$S$5)),1,0)+IF(ISNUMBER(SEARCH(MAP_TNHN!C7&" (1 tiết)",'PL11'!$S$6)),1,0)+IF(ISNUMBER(SEARCH(MAP_TNHN!C7&" (1 tiết)",'PL11'!$S$7)),1,0)+IF(ISNUMBER(SEARCH(MAP_TNHN!C7&" (1 tiết)",'PL11'!$S$8)),1,0)+IF(ISNUMBER(SEARCH(MAP_TNHN!C7&" (1 tiết)",'PL11'!$S$9)),1,0)+IF(ISNUMBER(SEARCH(MAP_TNHN!C7&" (1 tiết)",'PL11'!$S$10)),1,0)+IF(ISNUMBER(SEARCH(MAP_TNHN!C7&" (1 tiết)",'PL11'!$S$11)),1,0)+IF(ISNUMBER(SEARCH(MAP_TNHN!C7&" (1 tiết)",'PL11'!$S$12)),1,0)+IF(ISNUMBER(SEARCH(MAP_TNHN!C7&" (1 tiết)",'PL11'!$S$13)),1,0)+IF(ISNUMBER(SEARCH(MAP_TNHN!C7&" (1 tiết)",'PL11'!$S$14)),1,0)+IF(ISNUMBER(SEARCH(MAP_TNHN!C7&" (1 tiết)",'PL11'!$S$15)),1,0)+IF(ISNUMBER(SEARCH(MAP_TNHN!C7&" (1 tiết)",'PL11'!$S$16)),1,0)+IF(ISNUMBER(SEARCH(MAP_TNHN!C7&" (1 tiết)",'PL11'!$S$17)),1,0)+IF(ISNUMBER(SEARCH(MAP_TNHN!C7&" (1 tiết)",'PL11'!$S$18)),1,0))-(IF(ISNUMBER(SEARCH(MAP_TNHN!C7&" (2 tiết)",'PL11'!$S$5)),1,0)+IF(ISNUMBER(SEARCH(MAP_TNHN!C7&" (2 tiết)",'PL11'!$S$6)),1,0)+IF(ISNUMBER(SEARCH(MAP_TNHN!C7&" (2 tiết)",'PL11'!$S$7)),1,0)+IF(ISNUMBER(SEARCH(MAP_TNHN!C7&" (2 tiết)",'PL11'!$S$8)),1,0)+IF(ISNUMBER(SEARCH(MAP_TNHN!C7&" (2 tiết)",'PL11'!$S$9)),1,0)+IF(ISNUMBER(SEARCH(MAP_TNHN!C7&" (2 tiết)",'PL11'!$S$10)),1,0)+IF(ISNUMBER(SEARCH(MAP_TNHN!C7&" (2 tiết)",'PL11'!$S$11)),1,0)+IF(ISNUMBER(SEARCH(MAP_TNHN!C7&" (2 tiết)",'PL11'!$S$12)),1,0)+IF(ISNUMBER(SEARCH(MAP_TNHN!C7&" (2 tiết)",'PL11'!$S$13)),1,0)+IF(ISNUMBER(SEARCH(MAP_TNHN!C7&" (2 tiết)",'PL11'!$S$14)),1,0)+IF(ISNUMBER(SEARCH(MAP_TNHN!C7&" (2 tiết)",'PL11'!$S$15)),1,0)+IF(ISNUMBER(SEARCH(MAP_TNHN!C7&" (2 tiết)",'PL11'!$S$16)),1,0)+IF(ISNUMBER(SEARCH(MAP_TNHN!C7&" (2 tiết)",'PL11'!$S$17)),1,0)+IF(ISNUMBER(SEARCH(MAP_TNHN!C7&" (2 tiết)",'PL11'!$S$18)),1,0)))) -> 0 | AY7: =IF(S7="",0,IF(MAP_TNHN!D7="",S7*3,S7*3-2*(IF(ISNUMBER(SEARCH(MAP_TNHN!D7&" (1 tiết)",'PL10'!$S$5)),1,0)+IF(ISNUMBER(SEARCH(MAP_TNHN!D7&" (1 tiết)",'PL10'!$S$6)),1,0)+IF(ISNUMBER(SEARCH(MAP_TNHN!D7&" (1 tiết)",'PL10'!$S$7)),1,0)+IF(ISNUMBER(SEARCH(MAP_TNHN!D7&" (1 tiết)",'PL10'!$S$8)),1,0)+IF(ISNUMBER(SEARCH(MAP_TNHN!D7&" (1 tiết)",'PL10'!$S$9)),1,0)+IF(ISNUMBER(SEARCH(MAP_TNHN!D7&" (1 tiết)",'PL10'!$S$10)),1,0)+IF(ISNUMBER(SEARCH(MAP_TNHN!D7&" (1 tiết)",'PL10'!$S$11)),1,0)+IF(ISNUMBER(SEARCH(MAP_TNHN!D7&" (1 tiết)",'PL10'!$S$12)),1,0)+IF(ISNUMBER(SEARCH(MAP_TNHN!D7&" (1 tiết)",'PL10'!$S$13)),1,0)+IF(ISNUMBER(SEARCH(MAP_TNHN!D7&" (1 tiết)",'PL10'!$S$14)),1,0)+IF(ISNUMBER(SEARCH(MAP_TNHN!D7&" (1 tiết)",'PL10'!$S$15)),1,0)+IF(ISNUMBER(SEARCH(MAP_TNHN!D7&" (1 tiết)",'PL10'!$S$16)),1,0)+IF(ISNUMBER(SEARCH(MAP_TNHN!D7&" (1 tiết)",'PL10'!$S$17)),1,0)+IF(ISNUMBER(SEARCH(MAP_TNHN!D7&" (1 tiết)",'PL10'!$S$18)),1,0)+IF(ISNUMBER(SEARCH(MAP_TNHN!D7&" (1 tiết)",'PL10'!$S$19)),1,0)+IF(ISNUMBER(SEARCH(MAP_TNHN!D7&" (1 tiết)",'PL10'!$S$20)),1,0)+IF(ISNUMBER(SEARCH(MAP_TNHN!D7&" (1 tiết)",'PL10'!$S$21)),1,0)+IF(ISNUMBER(SEARCH(MAP_TNHN!D7&" (1 tiết)",'PL10'!$S$22)),1,0)+IF(ISNUMBER(SEARCH(MAP_TNHN!D7&" (1 tiết)",'PL10'!$S$23)),1,0)+IF(ISNUMBER(SEARCH(MAP_TNHN!D7&" (1 tiết)",'PL10'!$S$24)),1,0)+IF(ISNUMBER(SEARCH(MAP_TNHN!D7&" (1 tiết)",'PL10'!$S$25)),1,0))-(IF(ISNUMBER(SEARCH(MAP_TNHN!D7&" (2 tiết)",'PL10'!$S$5)),1,0)+IF(ISNUMBER(SEARCH(MAP_TNHN!D7&" (2 tiết)",'PL10'!$S$6)),1,0)+IF(ISNUMBER(SEARCH(MAP_TNHN!D7&" (2 tiết)",'PL10'!$S$7)),1,0)+IF(ISNUMBER(SEARCH(MAP_TNHN!D7&" (2 tiết)",'PL10'!$S$8)),1,0)+IF(ISNUMBER(SEARCH(MAP_TNHN!D7&" (2 tiết)",'PL10'!$S$9)),1,0)+IF(ISNUMBER(SEARCH(MAP_TNHN!D7&" (2 tiết)",'PL10'!$S$10)),1,0)+IF(ISNUMBER(SEARCH(MAP_TNHN!D7&" (2 tiết)",'PL10'!$S$11)),1,0)+IF(ISNUMBER(SEARCH(MAP_TNHN!D7&" (2 tiết)",'PL10'!$S$12)),1,0)+IF(ISNUMBER(SEARCH(MAP_TNHN!D7&" (2 tiết)",'PL10'!$S$13)),1,0)+IF(ISNUMBER(SEARCH(MAP_TNHN!D7&" (2 tiết)",'PL10'!$S$14)),1,0)+IF(ISNUMBER(SEARCH(MAP_TNHN!D7&" (2 tiết)",'PL10'!$S$15)),1,0)+IF(ISNUMBER(SEARCH(MAP_TNHN!D7&" (2 tiết)",'PL10'!$S$16)),1,0)+IF(ISNUMBER(SEARCH(MAP_TNHN!D7&" (2 tiết)",'PL10'!$S$17)),1,0)+IF(ISNUMBER(SEARCH(MAP_TNHN!D7&" (2 tiết)",'PL10'!$S$18)),1,0)+IF(ISNUMBER(SEARCH(MAP_TNHN!D7&" (2 tiết)",'PL10'!$S$19)),1,0)+IF(ISNUMBER(SEARCH(MAP_TNHN!D7&" (2 tiết)",'PL10'!$S$20)),1,0)+IF(ISNUMBER(SEARCH(MAP_TNHN!D7&" (2 tiết)",'PL10'!$S$21)),1,0)+IF(ISNUMBER(SEARCH(MAP_TNHN!D7&" (2 tiết)",'PL10'!$S$22)),1,0)+IF(ISNUMBER(SEARCH(MAP_TNHN!D7&" (2 tiết)",'PL10'!$S$23)),1,0)+IF(ISNUMBER(SEARCH(MAP_TNHN!D7&" (2 tiết)",'PL10'!$S$24)),1,0)+IF(ISNUMBER(SEARCH(MAP_TNHN!D7&" (2 tiết)",'PL10'!$S$25)),1,0)))) -> 1
B8: 3 | C8: ĐOÀN VĂN CHẤT | K8: 4 | N8: 1 | P8: 2 | U8: =E8*'Phân tiết'!$M$7+G8*('Phân tiết'!$M$21/3)+H8*'Phân tiết'!$L$26+AW8+J8*'Phân tiết'!$M$20+K8*'Phân tiết'!$I$7+M8*('Phân tiết'!$I$21/3)+AX8+O8*'Phân tiết'!$I$20+P8*'Phân tiết'!$E$7+R8*('Phân tiết'!$E$21/3)+AY8+T8*'Phân tiết'!$E$20 -> 20 | V8: =F8*4+L8*4+Q8*4 -> 0 | Z8: =SUM(U8:Y8) -> 20 | AA8: =Z8-17 -> 3 | AD8: =AB8*AC8*1.5 -> 0 | AG8: =AE8*AF8*1.5 -> 0 | AJ8: =AH8*AI8 -> 0 | AK8: =AA8*33+AD8+AG8+AJ8 -> 99 | AN8: X | AO8: X | AP8: X | AT8: X | AW8: =IF(I8="",0,IF(MAP_TNHN!B8="",I8*3,I8*3-2*(IF(ISNUMBER(SEARCH(MAP_TNHN!B8&" (1 tiết)",'PL12'!$S$5)),1,0)+IF(ISNUMBER(SEARCH(MAP_TNHN!B8&" (1 tiết)",'PL12'!$S$6)),1,0)+IF(ISNUMBER(SEARCH(MAP_TNHN!B8&" (1 tiết)",'PL12'!$S$7)),1,0)+IF(ISNUMBER(SEARCH(MAP_TNHN!B8&" (1 tiết)",'PL12'!$S$8)),1,0)+IF(ISNUMBER(SEARCH(MAP_TNHN!B8&" (1 tiết)",'PL12'!$S$9)),1,0)+IF(ISNUMBER(SEARCH(MAP_TNHN!B8&" (1 tiết)",'PL12'!$S$10)),1,0)+IF(ISNUMBER(SEARCH(MAP_TNHN!B8&" (1 tiết)",'PL12'!$S$11)),1,0)+IF(ISNUMBER(SEARCH(MAP_TNHN!B8&" (1 tiết)",'PL12'!$S$12)),1,0)+IF(ISNUMBER(SEARCH(MAP_TNHN!B8&" (1 tiết)",'PL12'!$S$13)),1,0)+IF(ISNUMBER(SEARCH(MAP_TNHN!B8&" (1 tiết)",'PL12'!$S$14)),1,0)+IF(ISNUMBER(SEARCH(MAP_TNHN!B8&" (1 tiết)",'PL12'!$S$15)),1,0)+IF(ISNUMBER(SEARCH(MAP_TNHN!B8&" (1 tiết)",'PL12'!$S$16)),1,0)+IF(ISNUMBER(SEARCH(MAP_TNHN!B8&" (1 tiết)",'PL12'!$S$17)),1,0)+IF(ISNUMBER(SEARCH(MAP_TNHN!B8&" (1 tiết)",'PL12'!$S$18)),1,0)+IF(ISNUMBER(SEARCH(MAP_TNHN!B8&" (1 tiết)",'PL12'!$S$19)),1,0))-(IF(ISNUMBER(SEARCH(MAP_TNHN!B8&" (2 tiết)",'PL12'!$S$5)),1,0)+IF(ISNUMBER(SEARCH(MAP_TNHN!B8&" (2 tiết)",'PL12'!$S$6)),1,0)+IF(ISNUMBER(SEARCH(MAP_TNHN!B8&" (2 tiết)",'PL12'!$S$7)),1,0)+IF(ISNUMBER(SEARCH(MAP_TNHN!B8&" (2 tiết)",'PL12'!$S$8)),1,0)+IF(ISNUMBER(SEARCH(MAP_TNHN!B8&" (2 tiết)",'PL12'!$S$9)),1,0)+IF(ISNUMBER(SEARCH(MAP_TNHN!B8&" (2 tiết)",'PL12'!$S$10)),1,0)+IF(ISNUMBER(SEARCH(MAP_TNHN!B8&" (2 tiết)",'PL12'!$S$11)),1,0)+IF(ISNUMBER(SEARCH(MAP_TNHN!B8&" (2 tiết)",'PL12'!$S$12)),1,0)+IF(ISNUMBER(SEARCH(MAP_TNHN!B8&" (2 tiết)",'PL12'!$S$13)),1,0)+IF(ISNUMBER(SEARCH(MAP_TNHN!B8&" (2 tiết)",'PL12'!$S$14)),1,0)+IF(ISNUMBER(SEARCH(MAP_TNHN!B8&" (2 tiết)",'PL12'!$S$15)),1,0)+IF(ISNUMBER(SEARCH(MAP_TNHN!B8&" (2 tiết)",'PL12'!$S$16)),1,0)+IF(ISNUMBER(SEARCH(MAP_TNHN!B8&" (2 tiết)",'PL12'!$S$17)),1,0)+IF(ISNUMBER(SEARCH(MAP_TNHN!B8&" (2 tiết)",'PL12'!$S$18)),1,0)+IF(ISNUMBER(SEARCH(MAP_TNHN!B8&" (2 tiết)",'PL12'!$S$19)),1,0)))) -> 0 | AX8: =IF(N8="",0,IF(MAP_TNHN!C8="",N8*3,N8*3-2*(IF(ISNUMBER(SEARCH(MAP_TNHN!C8&" (1 tiết)",'PL11'!$S$5)),1,0)+IF(ISNUMBER(SEARCH(MAP_TNHN!C8&" (1 tiết)",'PL11'!$S$6)),1,0)+IF(ISNUMBER(SEARCH(MAP_TNHN!C8&" (1 tiết)",'PL11'!$S$7)),1,0)+IF(ISNUMBER(SEARCH(MAP_TNHN!C8&" (1 tiết)",'PL11'!$S$8)),1,0)+IF(ISNUMBER(SEARCH(MAP_TNHN!C8&" (1 tiết)",'PL11'!$S$9)),1,0)+IF(ISNUMBER(SEARCH(MAP_TNHN!C8&" (1 tiết)",'PL11'!$S$10)),1,0)+IF(ISNUMBER(SEARCH(MAP_TNHN!C8&" (1 tiết)",'PL11'!$S$11)),1,0)+IF(ISNUMBER(SEARCH(MAP_TNHN!C8&" (1 tiết)",'PL11'!$S$12)),1,0)+IF(ISNUMBER(SEARCH(MAP_TNHN!C8&" (1 tiết)",'PL11'!$S$13)),1,0)+IF(ISNUMBER(SEARCH(MAP_TNHN!C8&" (1 tiết)",'PL11'!$S$14)),1,0)+IF(ISNUMBER(SEARCH(MAP_TNHN!C8&" (1 tiết)",'PL11'!$S$15)),1,0)+IF(ISNUMBER(SEARCH(MAP_TNHN!C8&" (1 tiết)",'PL11'!$S$16)),1,0)+IF(ISNUMBER(SEARCH(MAP_TNHN!C8&" (1 tiết)",'PL11'!$S$17)),1,0)+IF(ISNUMBER(SEARCH(MAP_TNHN!C8&" (1 tiết)",'PL11'!$S$18)),1,0))-(IF(ISNUMBER(SEARCH(MAP_TNHN!C8&" (2 tiết)",'PL11'!$S$5)),1,0)+IF(ISNUMBER(SEARCH(MAP_TNHN!C8&" (2 tiết)",'PL11'!$S$6)),1,0)+IF(ISNUMBER(SEARCH(MAP_TNHN!C8&" (2 tiết)",'PL11'!$S$7)),1,0)+IF(ISNUMBER(SEARCH(MAP_TNHN!C8&" (2 tiết)",'PL11'!$S$8)),1,0)+IF(ISNUMBER(SEARCH(MAP_TNHN!C8&" (2 tiết)",'PL11'!$S$9)),1,0)+IF(ISNUMBER(SEARCH(MAP_TNHN!C8&" (2 tiết)",'PL11'!$S$10)),1,0)+IF(ISNUMBER(SEARCH(MAP_TNHN!C8&" (2 tiết)",'PL11'!$S$11)),1,0)+IF(ISNUMBER(SEARCH(MAP_TNHN!C8&" (2 tiết)",'PL11'!$S$12)),1,0)+IF(ISNUMBER(SEARCH(MAP_TNHN!C8&" (2 tiết)",'PL11'!$S$13)),1,0)+IF(ISNUMBER(SEARCH(MAP_TNHN!C8&" (2 tiết)",'PL11'!$S$14)),1,0)+IF(ISNUMBER(SEARCH(MAP_TNHN!C8&" (2 tiết)",'PL11'!$S$15)),1,0)+IF(ISNUMBER(SEARCH(MAP_TNHN!C8&" (2 tiết)",'PL11'!$S$16)),1,0)+IF(ISNUMBER(SEARCH(MAP_TNHN!C8&" (2 tiết)",'PL11'!$S$17)),1,0)+IF(ISNUMBER(SEARCH(MAP_TNHN!C8&" (2 tiết)",'PL11'!$S$18)),1,0)))) -> 2 | AY8: =IF(S8="",0,IF(MAP_TNHN!D8="",S8*3,S8*3-2*(IF(ISNUMBER(SEARCH(MAP_TNHN!D8&" (1 tiết)",'PL10'!$S$5)),1,0)+IF(ISNUMBER(SEARCH(MAP_TNHN!D8&" (1 tiết)",'PL10'!$S$6)),1,0)+IF(ISNUMBER(SEARCH(MAP_TNHN!D8&" (1 tiết)",'PL10'!$S$7)),1,0)+IF(ISNUMBER(SEARCH(MAP_TNHN!D8&" (1 tiết)",'PL10'!$S$8)),1,0)+IF(ISNUMBER(SEARCH(MAP_TNHN!D8&" (1 tiết)",'PL10'!$S$9)),1,0)+IF(ISNUMBER(SEARCH(MAP_TNHN!D8&" (1 tiết)",'PL10'!$S$10)),1,0)+IF(ISNUMBER(SEARCH(MAP_TNHN!D8&" (1 tiết)",'PL10'!$S$11)),1,0)+IF(ISNUMBER(SEARCH(MAP_TNHN!D8&" (1 tiết)",'PL10'!$S$12)),1,0)+IF(ISNUMBER(SEARCH(MAP_TNHN!D8&" (1 tiết)",'PL10'!$S$13)),1,0)+IF(ISNUMBER(SEARCH(MAP_TNHN!D8&" (1 tiết)",'PL10'!$S$14)),1,0)+IF(ISNUMBER(SEARCH(MAP_TNHN!D8&" (1 tiết)",'PL10'!$S$15)),1,0)+IF(ISNUMBER(SEARCH(MAP_TNHN!D8&" (1 tiết)",'PL10'!$S$16)),1,0)+IF(ISNUMBER(SEARCH(MAP_TNHN!D8&" (1 tiết)",'PL10'!$S$17)),1,0)+IF(ISNUMBER(SEARCH(MAP_TNHN!D8&" (1 tiết)",'PL10'!$S$18)),1,0)+IF(ISNUMBER(SEARCH(MAP_TNHN!D8&" (1 tiết)",'PL10'!$S$19)),1,0)+IF(ISNUMBER(SEARCH(MAP_TNHN!D8&" (1 tiết)",'PL10'!$S$20)),1,0)+IF(ISNUMBER(SEARCH(MAP_TNHN!D8&" (1 tiết)",'PL10'!$S$21)),1,0)+IF(ISNUMBER(SEARCH(MAP_TNHN!D8&" (1 tiết)",'PL10'!$S$22)),1,0)+IF(ISNUMBER(SEARCH(MAP_TNHN!D8&" (1 tiết)",'PL10'!$S$23)),1,0)+IF(ISNUMBER(SEARCH(MAP_TNHN!D8&" (1 tiết)",'PL10'!$S$24)),1,0)+IF(ISNUMBER(SEARCH(MAP_TNHN!D8&" (1 tiết)",'PL10'!$S$25)),1,0))-(IF(ISNUMBER(SEARCH(MAP_TNHN!D8&" (2 tiết)",'PL10'!$S$5)),1,0)+IF(ISNUMBER(SEARCH(MAP_TNHN!D8&" (2 tiết)",'PL10'!$S$6)),1,0)+IF(ISNUMBER(SEARCH(MAP_TNHN!D8&" (2 tiết)",'PL10'!$S$7)),1,0)+IF(ISNUMBER(SEARCH(MAP_TNHN!D8&" (2 tiết)",'PL10'!$S$8)),1,0)+IF(ISNUMBER(SEARCH(MAP_TNHN!D8&" (2 tiết)",'PL10'!$S$9)),1,0)+IF(ISNUMBER(SEARCH(MAP_TNHN!D8&" (2 tiết)",'PL10'!$S$10)),1,0)+IF(ISNUMBER(SEARCH(MAP_TNHN!D8&" (2 tiết)",'PL10'!$S$11)),1,0)+IF(ISNUMBER(SEARCH(MAP_TNHN!D8&" (2 tiết)",'PL10'!$S$12)),1,0)+IF(ISNUMBER(SEARCH(MAP_TNHN!D8&" (2 tiết)",'PL10'!$S$13)),1,0)+IF(ISNUMBER(SEARCH(MAP_TNHN!D8&" (2 tiết)",'PL10'!$S$14)),1,0)+IF(ISNUMBER(SEARCH(MAP_TNHN!D8&" (2 tiết)",'PL10'!$S$15)),1,0)+IF(ISNUMBER(SEARCH(MAP_TNHN!D8&" (2 tiết)",'PL10'!$S$16)),1,0)+IF(ISNUMBER(SEARCH(MAP_TNHN!D8&" (2 tiết)",'PL10'!$S$17)),1,0)+IF(ISNUMBER(SEARCH(MAP_TNHN!D8&" (2 tiết)",'PL10'!$S$18)),1,0)+IF(ISNUMBER(SEARCH(MAP_TNHN!D8&" (2 tiết)",'PL10'!$S$19)),1,0)+IF(ISNUMBER(SEARCH(MAP_TNHN!D8&" (2 tiết)",'PL10'!$S$20)),1,0)+IF(ISNUMBER(SEARCH(MAP_TNHN!D8&" (2 tiết)",'PL10'!$S$21)),1,0)+IF(ISNUMBER(SEARCH(MAP_TNHN!D8&" (2 tiết)",'PL10'!$S$22)),1,0)+IF(ISNUMBER(SEARCH(MAP_TNHN!D8&" (2 tiết)",'PL10'!$S$23)),1,0)+IF(ISNUMBER(SEARCH(MAP_TNHN!D8&" (2 tiết)",'PL10'!$S$24)),1,0)+IF(ISNUMBER(SEARCH(MAP_TNHN!D8&" (2 tiết)",'PL10'!$S$25)),1,0)))) -> 0
B9: 4 | C9: NGUYỄN XUÂN THU | D9: 10 | E9: 2 | K9: 1 | P9: 3 | Q9: 1 | S9: 1 | U9: =E9*'Phân tiết'!$M$7+G9*('Phân tiết'!$M$21/3)+H9*'Phân tiết'!$L$26+AW9+J9*'Phân tiết'!$M$20+K9*'Phân tiết'!$I$7+M9*('Phân tiết'!$I$21/3)+AX9+O9*'Phân tiết'!$I$20+P9*'Phân tiết'!$E$7+R9*('Phân tiết'!$E$21/3)+AY9+T9*'Phân tiết'!$E$20 -> 19 | V9: =F9*4+L9*4+Q9*4 -> 4 | W9: TPCM | Y9: 1 | Z9: =SUM(U9:Y9) -> 24 | AA9: =Z9-17 -> 7 | AD9: =AB9*AC9*1.5 -> 0 | AE9: 2 | AF9: 15 | AG9: =AE9*AF9*1.5 -> 45 | AJ9: =AH9*AI9 -> 0 | AK9: =AA9*33+AD9+AG9+AJ9 -> 276 | AM9: Khối 10 | AO9: X | AP9: X | AQ9: X | AR9: X | AT9: X | AW9: =IF(I9="",0,IF(MAP_TNHN!B9="",I9*3,I9*3-2*(IF(ISNUMBER(SEARCH(MAP_TNHN!B9&" (1 tiết)",'PL12'!$S$5)),1,0)+IF(ISNUMBER(SEARCH(MAP_TNHN!B9&" (1 tiết)",'PL12'!$S$6)),1,0)+IF(ISNUMBER(SEARCH(MAP_TNHN!B9&" (1 tiết)",'PL12'!$S$7)),1,0)+IF(ISNUMBER(SEARCH(MAP_TNHN!B9&" (1 tiết)",'PL12'!$S$8)),1,0)+IF(ISNUMBER(SEARCH(MAP_TNHN!B9&" (1 tiết)",'PL12'!$S$9)),1,0)+IF(ISNUMBER(SEARCH(MAP_TNHN!B9&" (1 tiết)",'PL12'!$S$10)),1,0)+IF(ISNUMBER(SEARCH(MAP_TNHN!B9&" (1 tiết)",'PL12'!$S$11)),1,0)+IF(ISNUMBER(SEARCH(MAP_TNHN!B9&" (1 tiết)",'PL12'!$S$12)),1,0)+IF(ISNUMBER(SEARCH(MAP_TNHN!B9&" (1 tiết)",'PL12'!$S$13)),1,0)+IF(ISNUMBER(SEARCH(MAP_TNHN!B9&" (1 tiết)",'PL12'!$S$14)),1,0)+IF(ISNUMBER(SEARCH(MAP_TNHN!B9&" (1 tiết)",'PL12'!$S$15)),1,0)+IF(ISNUMBER(SEARCH(MAP_TNHN!B9&" (1 tiết)",'PL12'!$S$16)),1,0)+IF(ISNUMBER(SEARCH(MAP_TNHN!B9&" (1 tiết)",'PL12'!$S$17)),1,0)+IF(ISNUMBER(SEARCH(MAP_TNHN!B9&" (1 tiết)",'PL12'!$S$18)),1,0)+IF(ISNUMBER(SEARCH(MAP_TNHN!B9&" (1 tiết)",'PL12'!$S$19)),1,0))-(IF(ISNUMBER(SEARCH(MAP_TNHN!B9&" (2 tiết)",'PL12'!$S$5)),1,0)+IF(ISNUMBER(SEARCH(MAP_TNHN!B9&" (2 tiết)",'PL12'!$S$6)),1,0)+IF(ISNUMBER(SEARCH(MAP_TNHN!B9&" (2 tiết)",'PL12'!$S$7)),1,0)+IF(ISNUMBER(SEARCH(MAP_TNHN!B9&" (2 tiết)",'PL12'!$S$8)),1,0)+IF(ISNUMBER(SEARCH(MAP_TNHN!B9&" (2 tiết)",'PL12'!$S$9)),1,0)+IF(ISNUMBER(SEARCH(MAP_TNHN!B9&" (2 tiết)",'PL12'!$S$10)),1,0)+IF(ISNUMBER(SEARCH(MAP_TNHN!B9&" (2 tiết)",'PL12'!$S$11)),1,0)+IF(ISNUMBER(SEARCH(MAP_TNHN!B9&" (2 tiết)",'PL12'!$S$12)),1,0)+IF(ISNUMBER(SEARCH(MAP_TNHN!B9&" (2 tiết)",'PL12'!$S$13)),1,0)+IF(ISNUMBER(SEARCH(MAP_TNHN!B9&" (2 tiết)",'PL12'!$S$14)),1,0)+IF(ISNUMBER(SEARCH(MAP_TNHN!B9&" (2 tiết)",'PL12'!$S$15)),1,0)+IF(ISNUMBER(SEARCH(MAP_TNHN!B9&" (2 tiết)",'PL12'!$S$16)),1,0)+IF(ISNUMBER(SEARCH(MAP_TNHN!B9&" (2 tiết)",'PL12'!$S$17)),1,0)+IF(ISNUMBER(SEARCH(MAP_TNHN!B9&" (2 tiết)",'PL12'!$S$18)),1,0)+IF(ISNUMBER(SEARCH(MAP_TNHN!B9&" (2 tiết)",'PL12'!$S$19)),1,0)))) -> 0 | AX9: =IF(N9="",0,IF(MAP_TNHN!C9="",N9*3,N9*3-2*(IF(ISNUMBER(SEARCH(MAP_TNHN!C9&" (1 tiết)",'PL11'!$S$5)),1,0)+IF(ISNUMBER(SEARCH(MAP_TNHN!C9&" (1 tiết)",'PL11'!$S$6)),1,0)+IF(ISNUMBER(SEARCH(MAP_TNHN!C9&" (1 tiết)",'PL11'!$S$7)),1,0)+IF(ISNUMBER(SEARCH(MAP_TNHN!C9&" (1 tiết)",'PL11'!$S$8)),1,0)+IF(ISNUMBER(SEARCH(MAP_TNHN!C9&" (1 tiết)",'PL11'!$S$9)),1,0)+IF(ISNUMBER(SEARCH(MAP_TNHN!C9&" (1 tiết)",'PL11'!$S$10)),1,0)+IF(ISNUMBER(SEARCH(MAP_TNHN!C9&" (1 tiết)",'PL11'!$S$11)),1,0)+IF(ISNUMBER(SEARCH(MAP_TNHN!C9&" (1 tiết)",'PL11'!$S$12)),1,0)+IF(ISNUMBER(SEARCH(MAP_TNHN!C9&" (1 tiết)",'PL11'!$S$13)),1,0)+IF(ISNUMBER(SEARCH(MAP_TNHN!C9&" (1 tiết)",'PL11'!$S$14)),1,0)+IF(ISNUMBER(SEARCH(MAP_TNHN!C9&" (1 tiết)",'PL11'!$S$15)),1,0)+IF(ISNUMBER(SEARCH(MAP_TNHN!C9&" (1 tiết)",'PL11'!$S$16)),1,0)+IF(ISNUMBER(SEARCH(MAP_TNHN!C9&" (1 tiết)",'PL11'!$S$17)),1,0)+IF(ISNUMBER(SEARCH(MAP_TNHN!C9&" (1 tiết)",'PL11'!$S$18)),1,0))-(IF(ISNUMBER(SEARCH(MAP_TNHN!C9&" (2 tiết)",'PL11'!$S$5)),1,0)+IF(ISNUMBER(SEARCH(MAP_TNHN!C9&" (2 tiết)",'PL11'!$S$6)),1,0)+IF(ISNUMBER(SEARCH(MAP_TNHN!C9&" (2 tiết)",'PL11'!$S$7)),1,0)+IF(ISNUMBER(SEARCH(MAP_TNHN!C9&" (2 tiết)",'PL11'!$S$8)),1,0)+IF(ISNUMBER(SEARCH(MAP_TNHN!C9&" (2 tiết)",'PL11'!$S$9)),1,0)+IF(ISNUMBER(SEARCH(MAP_TNHN!C9&" (2 tiết)",'PL11'!$S$10)),1,0)+IF(ISNUMBER(SEARCH(MAP_TNHN!C9&" (2 tiết)",'PL11'!$S$11)),1,0)+IF(ISNUMBER(SEARCH(MAP_TNHN!C9&" (2 tiết)",'PL11'!$S$12)),1,0)+IF(ISNUMBER(SEARCH(MAP_TNHN!C9&" (2 tiết)",'PL11'!$S$13)),1,0)+IF(ISNUMBER(SEARCH(MAP_TNHN!C9&" (2 tiết)",'PL11'!$S$14)),1,0)+IF(ISNUMBER(SEARCH(MAP_TNHN!C9&" (2 tiết)",'PL11'!$S$15)),1,0)+IF(ISNUMBER(SEARCH(MAP_TNHN!C9&" (2 tiết)",'PL11'!$S$16)),1,0)+IF(ISNUMBER(SEARCH(MAP_TNHN!C9&" (2 tiết)",'PL11'!$S$17)),1,0)+IF(ISNUMBER(SEARCH(MAP_TNHN!C9&" (2 tiết)",'PL11'!$S$18)),1,0)))) -> 0 | AY9: =IF(S9="",0,IF(MAP_TNHN!D9="",S9*3,S9*3-2*(IF(ISNUMBER(SEARCH(MAP_TNHN!D9&" (1 tiết)",'PL10'!$S$5)),1,0)+IF(ISNUMBER(SEARCH(MAP_TNHN!D9&" (1 tiết)",'PL10'!$S$6)),1,0)+IF(ISNUMBER(SEARCH(MAP_TNHN!D9&" (1 tiết)",'PL10'!$S$7)),1,0)+IF(ISNUMBER(SEARCH(MAP_TNHN!D9&" (1 tiết)",'PL10'!$S$8)),1,0)+IF(ISNUMBER(SEARCH(MAP_TNHN!D9&" (1 tiết)",'PL10'!$S$9)),1,0)+IF(ISNUMBER(SEARCH(MAP_TNHN!D9&" (1 tiết)",'PL10'!$S$10)),1,0)+IF(ISNUMBER(SEARCH(MAP_TNHN!D9&" (1 tiết)",'PL10'!$S$11)),1,0)+IF(ISNUMBER(SEARCH(MAP_TNHN!D9&" (1 tiết)",'PL10'!$S$12)),1,0)+IF(ISNUMBER(SEARCH(MAP_TNHN!D9&" (1 tiết)",'PL10'!$S$13)),1,0)+IF(ISNUMBER(SEARCH(MAP_TNHN!D9&" (1 tiết)",'PL10'!$S$14)),1,0)+IF(ISNUMBER(SEARCH(MAP_TNHN!D9&" (1 tiết)",'PL10'!$S$15)),1,0)+IF(ISNUMBER(SEARCH(MAP_TNHN!D9&" (1 tiết)",'PL10'!$S$16)),1,0)+IF(ISNUMBER(SEARCH(MAP_TNHN!D9&" (1 tiết)",'PL10'!$S$17)),1,0)+IF(ISNUMBER(SEARCH(MAP_TNHN!D9&" (1 tiết)",'PL10'!$S$18)),1,0)+IF(ISNUMBER(SEARCH(MAP_TNHN!D9&" (1 tiết)",'PL10'!$S$19)),1,0)+IF(ISNUMBER(SEARCH(MAP_TNHN!D9&" (1 tiết)",'PL10'!$S$20)),1,0)+IF(ISNUMBER(SEARCH(MAP_TNHN!D9&" (1 tiết)",'PL10'!$S$21)),1,0)+IF(ISNUMBER(SEARCH(MAP_TNHN!D9&" (1 tiết)",'PL10'!$S$22)),1,0)+IF(ISNUMBER(SEARCH(MAP_TNHN!D9&" (1 tiết)",'PL10'!$S$23)),1,0)+IF(ISNUMBER(SEARCH(MAP_TNHN!D9&" (1 tiết)",'PL10'!$S$24)),1,0)+IF(ISNUMBER(SEARCH(MAP_TNHN!D9&" (1 tiết)",'PL10'!$S$25)),1,0))-(IF(ISNUMBER(SEARCH(MAP_TNHN!D9&" (2 tiết)",'PL10'!$S$5)),1,0)+IF(ISNUMBER(SEARCH(MAP_TNHN!D9&" (2 tiết)",'PL10'!$S$6)),1,0)+IF(ISNUMBER(SEARCH(MAP_TNHN!D9&" (2 tiết)",'PL10'!$S$7)),1,0)+IF(ISNUMBER(SEARCH(MAP_TNHN!D9&" (2 tiết)",'PL10'!$S$8)),1,0)+IF(ISNUMBER(SEARCH(MAP_TNHN!D9&" (2 tiết)",'PL10'!$S$9)),1,0)+IF(ISNUMBER(SEARCH(MAP_TNHN!D9&" (2 tiết)",'PL10'!$S$10)),1,0)+IF(ISNUMBER(SEARCH(MAP_TNHN!D9&" (2 tiết)",'PL10'!$S$11)),1,0)+IF(ISNUMBER(SEARCH(MAP_TNHN!D9&" (2 tiết)",'PL10'!$S$12)),1,0)+IF(ISNUMBER(SEARCH(MAP_TNHN!D9&" (2 tiết)",'PL10'!$S$13)),1,0)+IF(ISNUMBER(SEARCH(MAP_TNHN!D9&" (2 tiết)",'PL10'!$S$14)),1,0)+IF(ISNUMBER(SEARCH(MAP_TNHN!D9&" (2 tiết)",'PL10'!$S$15)),1,0)+IF(ISNUMBER(SEARCH(MAP_TNHN!D9&" (2 tiết)",'PL10'!$S$16)),1,0)+IF(ISNUMBER(SEARCH(MAP_TNHN!D9&" (2 tiết)",'PL10'!$S$17)),1,0)+IF(ISNUMBER(SEARCH(MAP_TNHN!D9&" (2 tiết)",'PL10'!$S$18)),1,0)+IF(ISNUMBER(SEARCH(MAP_TNHN!D9&" (2 tiết)",'PL10'!$S$19)),1,0)+IF(ISNUMBER(SEARCH(MAP_TNHN!D9&" (2 tiết)",'PL10'!$S$20)),1,0)+IF(ISNUMBER(SEARCH(MAP_TNHN!D9&" (2 tiết)",'PL10'!$S$21)),1,0)+IF(ISNUMBER(SEARCH(MAP_TNHN!D9&" (2 tiết)",'PL10'!$S$22)),1,0)+IF(ISNUMBER(SEARCH(MAP_TNHN!D9&" (2 tiết)",'PL10'!$S$23)),1,0)+IF(ISNUMBER(SEARCH(MAP_TNHN!D9&" (2 tiết)",'PL10'!$S$24)),1,0)+IF(ISNUMBER(SEARCH(MAP_TNHN!D9&" (2 tiết)",'PL10'!$S$25)),1,0)))) -> 1
B10: 5 | C10: PHẠM THỊ PHƯƠNG ĐIỀN | D10: 12 | E10: 2 | F10: 1 | H10: 2 | K10: 2 | U10: =E10*'Phân tiết'!$M$7+G10*('Phân tiết'!$M$21/3)+H10*'Phân tiết'!$L$26+AW10+J10*'Phân tiết'!$M$20+K10*'Phân tiết'!$I$7+M10*('Phân tiết'!$I$21/3)+AX10+O10*'Phân tiết'!$I$20+P10*'Phân tiết'!$E$7+R10*('Phân tiết'!$E$21/3)+AY10+T10*'Phân tiết'!$E$20 -> 16 | V10: =F10*4+L10*4+Q10*4 -> 4 | X10: TTCĐ | Y10: 1 | Z10: =SUM(U10:Y10) -> 21 | AA10: =Z10-17 -> 4 | AD10: =AB10*AC10*1.5 -> 0 | AE10: 2 | AF10: 18 | AG10: =AE10*AF10*1.5 -> 54 | AJ10: =AH10*AI10 -> 0 | AK10: =AA10*33+AD10+AG10+AJ10 -> 186 | AM10: Khôi 12 | AO10: X | AP10: X | AQ10: X | AR10: X | AT10: X | AW10: =IF(I10="",0,IF(MAP_TNHN!B10="",I10*3,I10*3-2*(IF(ISNUMBER(SEARCH(MAP_TNHN!B10&" (1 tiết)",'PL12'!$S$5)),1,0)+IF(ISNUMBER(SEARCH(MAP_TNHN!B10&" (1 tiết)",'PL12'!$S$6)),1,0)+IF(ISNUMBER(SEARCH(MAP_TNHN!B10&" (1 tiết)",'PL12'!$S$7)),1,0)+IF(ISNUMBER(SEARCH(MAP_TNHN!B10&" (1 tiết)",'PL12'!$S$8)),1,0)+IF(ISNUMBER(SEARCH(MAP_TNHN!B10&" (1 tiết)",'PL12'!$S$9)),1,0)+IF(ISNUMBER(SEARCH(MAP_TNHN!B10&" (1 tiết)",'PL12'!$S$10)),1,0)+IF(ISNUMBER(SEARCH(MAP_TNHN!B10&" (1 tiết)",'PL12'!$S$11)),1,0)+IF(ISNUMBER(SEARCH(MAP_TNHN!B10&" (1 tiết)",'PL12'!$S$12)),1,0)+IF(ISNUMBER(SEARCH(MAP_TNHN!B10&" (1 tiết)",'PL12'!$S$13)),1,0)+IF(ISNUMBER(SEARCH(MAP_TNHN!B10&" (1 tiết)",'PL12'!$S$14)),1,0)+IF(ISNUMBER(SEARCH(MAP_TNHN!B10&" (1 tiết)",'PL12'!$S$15)),1,0)+IF(ISNUMBER(SEARCH(MAP_TNHN!B10&" (1 tiết)",'PL12'!$S$16)),1,0)+IF(ISNUMBER(SEARCH(MAP_TNHN!B10&" (1 tiết)",'PL12'!$S$17)),1,0)+IF(ISNUMBER(SEARCH(MAP_TNHN!B10&" (1 tiết)",'PL12'!$S$18)),1,0)+IF(ISNUMBER(SEARCH(MAP_TNHN!B10&" (1 tiết)",'PL12'!$S$19)),1,0))-(IF(ISNUMBER(SEARCH(MAP_TNHN!B10&" (2 tiết)",'PL12'!$S$5)),1,0)+IF(ISNUMBER(SEARCH(MAP_TNHN!B10&" (2 tiết)",'PL12'!$S$6)),1,0)+IF(ISNUMBER(SEARCH(MAP_TNHN!B10&" (2 tiết)",'PL12'!$S$7)),1,0)+IF(ISNUMBER(SEARCH(MAP_TNHN!B10&" (2 tiết)",'PL12'!$S$8)),1,0)+IF(ISNUMBER(SEARCH(MAP_TNHN!B10&" (2 tiết)",'PL12'!$S$9)),1,0)+IF(ISNUMBER(SEARCH(MAP_TNHN!B10&" (2 tiết)",'PL12'!$S$10)),1,0)+IF(ISNUMBER(SEARCH(MAP_TNHN!B10&" (2 tiết)",'PL12'!$S$11)),1,0)+IF(ISNUMBER(SEARCH(MAP_TNHN!B10&" (2 tiết)",'PL12'!$S$12)),1,0)+IF(ISNUMBER(SEARCH(MAP_TNHN!B10&" (2 tiết)",'PL12'!$S$13)),1,0)+IF(ISNUMBER(SEARCH(MAP_TNHN!B10&" (2 tiết)",'PL12'!$S$14)),1,0)+IF(ISNUMBER(SEARCH(MAP_TNHN!B10&" (2 tiết)",'PL12'!$S$15)),1,0)+IF(ISNUMBER(SEARCH(MAP_TNHN!B10&" (2 tiết)",'PL12'!$S$16)),1,0)+IF(ISNUMBER(SEARCH(MAP_TNHN!B10&" (2 tiết)",'PL12'!$S$17)),1,0)+IF(ISNUMBER(SEARCH(MAP_TNHN!B10&" (2 tiết)",'PL12'!$S$18)),1,0)+IF(ISNUMBER(SEARCH(MAP_TNHN!B10&" (2 tiết)",'PL12'!$S$19)),1,0)))) -> 0 | AX10: =IF(N10="",0,IF(MAP_TNHN!C10="",N10*3,N10*3-2*(IF(ISNUMBER(SEARCH(MAP_TNHN!C10&" (1 tiết)",'PL11'!$S$5)),1,0)+IF(ISNUMBER(SEARCH(MAP_TNHN!C10&" (1 tiết)",'PL11'!$S$6)),1,0)+IF(ISNUMBER(SEARCH(MAP_TNHN!C10&" (1 tiết)",'PL11'!$S$7)),1,0)+IF(ISNUMBER(SEARCH(MAP_TNHN!C10&" (1 tiết)",'PL11'!$S$8)),1,0)+IF(ISNUMBER(SEARCH(MAP_TNHN!C10&" (1 tiết)",'PL11'!$S$9)),1,0)+IF(ISNUMBER(SEARCH(MAP_TNHN!C10&" (1 tiết)",'PL11'!$S$10)),1,0)+IF(ISNUMBER(SEARCH(MAP_TNHN!C10&" (1 tiết)",'PL11'!$S$11)),1,0)+IF(ISNUMBER(SEARCH(MAP_TNHN!C10&" (1 tiết)",'PL11'!$S$12)),1,0)+IF(ISNUMBER(SEARCH(MAP_TNHN!C10&" (1 tiết)",'PL11'!$S$13)),1,0)+IF(ISNUMBER(SEARCH(MAP_TNHN!C10&" (1 tiết)",'PL11'!$S$14)),1,0)+IF(ISNUMBER(SEARCH(MAP_TNHN!C10&" (1 tiết)",'PL11'!$S$15)),1,0)+IF(ISNUMBER(SEARCH(MAP_TNHN!C10&" (1 tiết)",'PL11'!$S$16)),1,0)+IF(ISNUMBER(SEARCH(MAP_TNHN!C10&" (1 tiết)",'PL11'!$S$17)),1,0)+IF(ISNUMBER(SEARCH(MAP_TNHN!C10&" (1 tiết)",'PL11'!$S$18)),1,0))-(IF(ISNUMBER(SEARCH(MAP_TNHN!C10&" (2 tiết)",'PL11'!$S$5)),1,0)+IF(ISNUMBER(SEARCH(MAP_TNHN!C10&" (2 tiết)",'PL11'!$S$6)),1,0)+IF(ISNUMBER(SEARCH(MAP_TNHN!C10&" (2 tiết)",'PL11'!$S$7)),1,0)+IF(ISNUMBER(SEARCH(MAP_TNHN!C10&" (2 tiết)",'PL11'!$S$8)),1,0)+IF(ISNUMBER(SEARCH(MAP_TNHN!C10&" (2 tiết)",'PL11'!$S$9)),1,0)+IF(ISNUMBER(SEARCH(MAP_TNHN!C10&" (2 tiết)",'PL11'!$S$10)),1,0)+IF(ISNUMBER(SEARCH(MAP_TNHN!C10&" (2 tiết)",'PL11'!$S$11)),1,0)+IF(ISNUMBER(SEARCH(MAP_TNHN!C10&" (2 tiết)",'PL11'!$S$12)),1,0)+IF(ISNUMBER(SEARCH(MAP_TNHN!C10&" (2 tiết)",'PL11'!$S$13)),1,0)+IF(ISNUMBER(SEARCH(MAP_TNHN!C10&" (2 tiết)",'PL11'!$S$14)),1,0)+IF(ISNUMBER(SEARCH(MAP_TNHN!C10&" (2 tiết)",'PL11'!$S$15)),1,0)+IF(ISNUMBER(SEARCH(MAP_TNHN!C10&" (2 tiết)",'PL11'!$S$16)),1,0)+IF(ISNUMBER(SEARCH(MAP_TNHN!C10&" (2 tiết)",'PL11'!$S$17)),1,0)+IF(ISNUMBER(SEARCH(MAP_TNHN!C10&" (2 tiết)",'PL11'!$S$18)),1,0)))) -> 0 | AY10: =IF(S10="",0,IF(MAP_TNHN!D10="",S10*3,S10*3-2*(IF(ISNUMBER(SEARCH(MAP_TNHN!D10&" (1 tiết)",'PL10'!$S$5)),1,0)+IF(ISNUMBER(SEARCH(MAP_TNHN!D10&" (1 tiết)",'PL10'!$S$6)),1,0)+IF(ISNUMBER(SEARCH(MAP_TNHN!D10&" (1 tiết)",'PL10'!$S$7)),1,0)+IF(ISNUMBER(SEARCH(MAP_TNHN!D10&" (1 tiết)",'PL10'!$S$8)),1,0)+IF(ISNUMBER(SEARCH(MAP_TNHN!D10&" (1 tiết)",'PL10'!$S$9)),1,0)+IF(ISNUMBER(SEARCH(MAP_TNHN!D10&" (1 tiết)",'PL10'!$S$10)),1,0)+IF(ISNUMBER(SEARCH(MAP_TNHN!D10&" (1 tiết)",'PL10'!$S$11)),1,0)+IF(ISNUMBER(SEARCH(MAP_TNHN!D10&" (1 tiết)",'PL10'!$S$12)),1,0)+IF(ISNUMBER(SEARCH(MAP_TNHN!D10&" (1 tiết)",'PL10'!$S$13)),1,0)+IF(ISNUMBER(SEARCH(MAP_TNHN!D10&" (1 tiết)",'PL10'!$S$14)),1,0)+IF(ISNUMBER(SEARCH(MAP_TNHN!D10&" (1 tiết)",'PL10'!$S$15)),1,0)+IF(ISNUMBER(SEARCH(MAP_TNHN!D10&" (1 tiết)",'PL10'!$S$16)),1,0)+IF(ISNUMBER(SEARCH(MAP_TNHN!D10&" (1 tiết)",'PL10'!$S$17)),1,0)+IF(ISNUMBER(SEARCH(MAP_TNHN!D10&" (1 tiết)",'PL10'!$S$18)),1,0)+IF(ISNUMBER(SEARCH(MAP_TNHN!D10&" (1 tiết)",'PL10'!$S$19)),1,0)+IF(ISNUMBER(SEARCH(MAP_TNHN!D10&" (1 tiết)",'PL10'!$S$20)),1,0)+IF(ISNUMBER(SEARCH(MAP_TNHN!D10&" (1 tiết)",'PL10'!$S$21)),1,0)+IF(ISNUMBER(SEARCH(MAP_TNHN!D10&" (1 tiết)",'PL10'!$S$22)),1,0)+IF(ISNUMBER(SEARCH(MAP_TNHN!D10&" (1 tiết)",'PL10'!$S$23)),1,0)+IF(ISNUMBER(SEARCH(MAP_TNHN!D10&" (1 tiết)",'PL10'!$S$24)),1,0)+IF(ISNUMBER(SEARCH(MAP_TNHN!D10&" (1 tiết)",'PL10'!$S$25)),1,0))-(IF(ISNUMBER(SEARCH(MAP_TNHN!D10&" (2 tiết)",'PL10'!$S$5)),1,0)+IF(ISNUMBER(SEARCH(MAP_TNHN!D10&" (2 tiết)",'PL10'!$S$6)),1,0)+IF(ISNUMBER(SEARCH(MAP_TNHN!D10&" (2 tiết)",'PL10'!$S$7)),1,0)+IF(ISNUMBER(SEARCH(MAP_TNHN!D10&" (2 tiết)",'PL10'!$S$8)),1,0)+IF(ISNUMBER(SEARCH(MAP_TNHN!D10&" (2 tiết)",'PL10'!$S$9)),1,0)+IF(ISNUMBER(SEARCH(MAP_TNHN!D10&" (2 tiết)",'PL10'!$S$10)),1,0)+IF(ISNUMBER(SEARCH(MAP_TNHN!D10&" (2 tiết)",'PL10'!$S$11)),1,0)+IF(ISNUMBER(SEARCH(MAP_TNHN!D10&" (2 tiết)",'PL10'!$S$12)),1,0)+IF(ISNUMBER(SEARCH(MAP_TNHN!D10&" (2 tiết)",'PL10'!$S$13)),1,0)+IF(ISNUMBER(SEARCH(MAP_TNHN!D10&" (2 tiết)",'PL10'!$S$14)),1,0)+IF(ISNUMBER(SEARCH(MAP_TNHN!D10&" (2 tiết)",'PL10'!$S$15)),1,0)+IF(ISNUMBER(SEARCH(MAP_TNHN!D10&" (2 tiết)",'PL10'!$S$16)),1,0)+IF(ISNUMBER(SEARCH(MAP_TNHN!D10&" (2 tiết)",'PL10'!$S$17)),1,0)+IF(ISNUMBER(SEARCH(MAP_TNHN!D10&" (2 tiết)",'PL10'!$S$18)),1,0)+IF(ISNUMBER(SEARCH(MAP_TNHN!D10&" (2 tiết)",'PL10'!$S$19)),1,0)+IF(ISNUMBER(SEARCH(MAP_TNHN!D10&" (2 tiết)",'PL10'!$S$20)),1,0)+IF(ISNUMBER(SEARCH(MAP_TNHN!D10&" (2 tiết)",'PL10'!$S$21)),1,0)+IF(ISNUMBER(SEARCH(MAP_TNHN!D10&" (2 tiết)",'PL10'!$S$22)),1,0)+IF(ISNUMBER(SEARCH(MAP_TNHN!D10&" (2 tiết)",'PL10'!$S$23)),1,0)+IF(ISNUMBER(SEARCH(MAP_TNHN!D10&" (2 tiết)",'PL10'!$S$24)),1,0)+IF(ISNUMBER(SEARCH(MAP_TNHN!D10&" (2 tiết)",'PL10'!$S$25)),1,0)))) -> 0
B11: 6 | C11: MAI LAN ANH | D11: 10 | K11: 3 | P11: 3 | Q11: 1 | S11: 1 | U11: =E11*'Phân tiết'!$M$7+G11*('Phân tiết'!$M$21/3)+H11*'Phân tiết'!$L$26+AW11+J11*'Phân tiết'!$M$20+K11*'Phân tiết'!$I$7+M11*('Phân tiết'!$I$21/3)+AX11+O11*'Phân tiết'!$I$20+P11*'Phân tiết'!$E$7+R11*('Phân tiết'!$E$21/3)+AY11+T11*'Phân tiết'!$E$20 -> 19 | V11: =F11*4+L11*4+Q11*4 -> 4 | Z11: =SUM(U11:Y11) -> 23 | AA11: =Z11-17 -> 6 | AD11: =AB11*AC11*1.5 -> 0 | AE11: 2 | AF11: 15 | AG11: =AE11*AF11*1.5 -> 45 | AJ11: =AH11*AI11 -> 0 | AK11: =AA11*33+AD11+AG11+AJ11 -> 243 | AM11: Khối 11 | AO11: X | AP11: X | AQ11: X | AR11: X | AT11: X | AW11: =IF(I11="",0,IF(MAP_TNHN!B11="",I11*3,I11*3-2*(IF(ISNUMBER(SEARCH(MAP_TNHN!B11&" (1 tiết)",'PL12'!$S$5)),1,0)+IF(ISNUMBER(SEARCH(MAP_TNHN!B11&" (1 tiết)",'PL12'!$S$6)),1,0)+IF(ISNUMBER(SEARCH(MAP_TNHN!B11&" (1 tiết)",'PL12'!$S$7)),1,0)+IF(ISNUMBER(SEARCH(MAP_TNHN!B11&" (1 tiết)",'PL12'!$S$8)),1,0)+IF(ISNUMBER(SEARCH(MAP_TNHN!B11&" (1 tiết)",'PL12'!$S$9)),1,0)+IF(ISNUMBER(SEARCH(MAP_TNHN!B11&" (1 tiết)",'PL12'!$S$10)),1,0)+IF(ISNUMBER(SEARCH(MAP_TNHN!B11&" (1 tiết)",'PL12'!$S$11)),1,0)+IF(ISNUMBER(SEARCH(MAP_TNHN!B11&" (1 tiết)",'PL12'!$S$12)),1,0)+IF(ISNUMBER(SEARCH(MAP_TNHN!B11&" (1 tiết)",'PL12'!$S$13)),1,0)+IF(ISNUMBER(SEARCH(MAP_TNHN!B11&" (1 tiết)",'PL12'!$S$14)),1,0)+IF(ISNUMBER(SEARCH(MAP_TNHN!B11&" (1 tiết)",'PL12'!$S$15)),1,0)+IF(ISNUMBER(SEARCH(MAP_TNHN!B11&" (1 tiết)",'PL12'!$S$16)),1,0)+IF(ISNUMBER(SEARCH(MAP_TNHN!B11&" (1 tiết)",'PL12'!$S$17)),1,0)+IF(ISNUMBER(SEARCH(MAP_TNHN!B11&" (1 tiết)",'PL12'!$S$18)),1,0)+IF(ISNUMBER(SEARCH(MAP_TNHN!B11&" (1 tiết)",'PL12'!$S$19)),1,0))-(IF(ISNUMBER(SEARCH(MAP_TNHN!B11&" (2 tiết)",'PL12'!$S$5)),1,0)+IF(ISNUMBER(SEARCH(MAP_TNHN!B11&" (2 tiết)",'PL12'!$S$6)),1,0)+IF(ISNUMBER(SEARCH(MAP_TNHN!B11&" (2 tiết)",'PL12'!$S$7)),1,0)+IF(ISNUMBER(SEARCH(MAP_TNHN!B11&" (2 tiết)",'PL12'!$S$8)),1,0)+IF(ISNUMBER(SEARCH(MAP_TNHN!B11&" (2 tiết)",'PL12'!$S$9)),1,0)+IF(ISNUMBER(SEARCH(MAP_TNHN!B11&" (2 tiết)",'PL12'!$S$10)),1,0)+IF(ISNUMBER(SEARCH(MAP_TNHN!B11&" (2 tiết)",'PL12'!$S$11)),1,0)+IF(ISNUMBER(SEARCH(MAP_TNHN!B11&" (2 tiết)",'PL12'!$S$12)),1,0)+IF(ISNUMBER(SEARCH(MAP_TNHN!B11&" (2 tiết)",'PL12'!$S$13)),1,0)+IF(ISNUMBER(SEARCH(MAP_TNHN!B11&" (2 tiết)",'PL12'!$S$14)),1,0)+IF(ISNUMBER(SEARCH(MAP_TNHN!B11&" (2 tiết)",'PL12'!$S$15)),1,0)+IF(ISNUMBER(SEARCH(MAP_TNHN!B11&" (2 tiết)",'PL12'!$S$16)),1,0)+IF(ISNUMBER(SEARCH(MAP_TNHN!B11&" (2 tiết)",'PL12'!$S$17)),1,0)+IF(ISNUMBER(SEARCH(MAP_TNHN!B11&" (2 tiết)",'PL12'!$S$18)),1,0)+IF(ISNUMBER(SEARCH(MAP_TNHN!B11&" (2 tiết)",'PL12'!$S$19)),1,0)))) -> 0 | AX11: =IF(N11="",0,IF(MAP_TNHN!C11="",N11*3,N11*3-2*(IF(ISNUMBER(SEARCH(MAP_TNHN!C11&" (1 tiết)",'PL11'!$S$5)),1,0)+IF(ISNUMBER(SEARCH(MAP_TNHN!C11&" (1 tiết)",'PL11'!$S$6)),1,0)+IF(ISNUMBER(SEARCH(MAP_TNHN!C11&" (1 tiết)",'PL11'!$S$7)),1,0)+IF(ISNUMBER(SEARCH(MAP_TNHN!C11&" (1 tiết)",'PL11'!$S$8)),1,0)+IF(ISNUMBER(SEARCH(MAP_TNHN!C11&" (1 tiết)",'PL11'!$S$9)),1,0)+IF(ISNUMBER(SEARCH(MAP_TNHN!C11&" (1 tiết)",'PL11'!$S$10)),1,0)+IF(ISNUMBER(SEARCH(MAP_TNHN!C11&" (1 tiết)",'PL11'!$S$11)),1,0)+IF(ISNUMBER(SEARCH(MAP_TNHN!C11&" (1 tiết)",'PL11'!$S$12)),1,0)+IF(ISNUMBER(SEARCH(MAP_TNHN!C11&" (1 tiết)",'PL11'!$S$13)),1,0)+IF(ISNUMBER(SEARCH(MAP_TNHN!C11&" (1 tiết)",'PL11'!$S$14)),1,0)+IF(ISNUMBER(SEARCH(MAP_TNHN!C11&" (1 tiết)",'PL11'!$S$15)),1,0)+IF(ISNUMBER(SEARCH(MAP_TNHN!C11&" (1 tiết)",'PL11'!$S$16)),1,0)+IF(ISNUMBER(SEARCH(MAP_TNHN!C11&" (1 tiết)",'PL11'!$S$17)),1,0)+IF(ISNUMBER(SEARCH(MAP_TNHN!C11&" (1 tiết)",'PL11'!$S$18)),1,0))-(IF(ISNUMBER(SEARCH(MAP_TNHN!C11&" (2 tiết)",'PL11'!$S$5)),1,0)+IF(ISNUMBER(SEARCH(MAP_TNHN!C11&" (2 tiết)",'PL11'!$S$6)),1,0)+IF(ISNUMBER(SEARCH(MAP_TNHN!C11&" (2 tiết)",'PL11'!$S$7)),1,0)+IF(ISNUMBER(SEARCH(MAP_TNHN!C11&" (2 tiết)",'PL11'!$S$8)),1,0)+IF(ISNUMBER(SEARCH(MAP_TNHN!C11&" (2 tiết)",'PL11'!$S$9)),1,0)+IF(ISNUMBER(SEARCH(MAP_TNHN!C11&" (2 tiết)",'PL11'!$S$10)),1,0)+IF(ISNUMBER(SEARCH(MAP_TNHN!C11&" (2 tiết)",'PL11'!$S$11)),1,0)+IF(ISNUMBER(SEARCH(MAP_TNHN!C11&" (2 tiết)",'PL11'!$S$12)),1,0)+IF(ISNUMBER(SEARCH(MAP_TNHN!C11&" (2 tiết)",'PL11'!$S$13)),1,0)+IF(ISNUMBER(SEARCH(MAP_TNHN!C11&" (2 tiết)",'PL11'!$S$14)),1,0)+IF(ISNUMBER(SEARCH(MAP_TNHN!C11&" (2 tiết)",'PL11'!$S$15)),1,0)+IF(ISNUMBER(SEARCH(MAP_TNHN!C11&" (2 tiết)",'PL11'!$S$16)),1,0)+IF(ISNUMBER(SEARCH(MAP_TNHN!C11&" (2 tiết)",'PL11'!$S$17)),1,0)+IF(ISNUMBER(SEARCH(MAP_TNHN!C11&" (2 tiết)",'PL11'!$S$18)),1,0)))) -> 0 | AY11: =IF(S11="",0,IF(MAP_TNHN!D11="",S11*3,S11*3-2*(IF(ISNUMBER(SEARCH(MAP_TNHN!D11&" (1 tiết)",'PL10'!$S$5)),1,0)+IF(ISNUMBER(SEARCH(MAP_TNHN!D11&" (1 tiết)",'PL10'!$S$6)),1,0)+IF(ISNUMBER(SEARCH(MAP_TNHN!D11&" (1 tiết)",'PL10'!$S$7)),1,0)+IF(ISNUMBER(SEARCH(MAP_TNHN!D11&" (1 tiết)",'PL10'!$S$8)),1,0)+IF(ISNUMBER(SEARCH(MAP_TNHN!D11&" (1 tiết)",'PL10'!$S$9)),1,0)+IF(ISNUMBER(SEARCH(MAP_TNHN!D11&" (1 tiết)",'PL10'!$S$10)),1,0)+IF(ISNUMBER(SEARCH(MAP_TNHN!D11&" (1 tiết)",'PL10'!$S$11)),1,0)+IF(ISNUMBER(SEARCH(MAP_TNHN!D11&" (1 tiết)",'PL10'!$S$12)),1,0)+IF(ISNUMBER(SEARCH(MAP_TNHN!D11&" (1 tiết)",'PL10'!$S$13)),1,0)+IF(ISNUMBER(SEARCH(MAP_TNHN!D11&" (1 tiết)",'PL10'!$S$14)),1,0)+IF(ISNUMBER(SEARCH(MAP_TNHN!D11&" (1 tiết)",'PL10'!$S$15)),1,0)+IF(ISNUMBER(SEARCH(MAP_TNHN!D11&" (1 tiết)",'PL10'!$S$16)),1,0)+IF(ISNUMBER(SEARCH(MAP_TNHN!D11&" (1 tiết)",'PL10'!$S$17)),1,0)+IF(ISNUMBER(SEARCH(MAP_TNHN!D11&" (1 tiết)",'PL10'!$S$18)),1,0)+IF(ISNUMBER(SEARCH(MAP_TNHN!D11&" (1 tiết)",'PL10'!$S$19)),1,0)+IF(ISNUMBER(SEARCH(MAP_TNHN!D11&" (1 tiết)",'PL10'!$S$20)),1,0)+IF(ISNUMBER(SEARCH(MAP_TNHN!D11&" (1 tiết)",'PL10'!$S$21)),1,0)+IF(ISNUMBER(SEARCH(MAP_TNHN!D11&" (1 tiết)",'PL10'!$S$22)),1,0)+IF(ISNUMBER(SEARCH(MAP_TNHN!D11&" (1 tiết)",'PL10'!$S$23)),1,0)+IF(ISNUMBER(SEARCH(MAP_TNHN!D11&" (1 tiết)",'PL10'!$S$24)),1,0)+IF(ISNUMBER(SEARCH(MAP_TNHN!D11&" (1 tiết)",'PL10'!$S$25)),1,0))-(IF(ISNUMBER(SEARCH(MAP_TNHN!D11&" (2 tiết)",'PL10'!$S$5)),1,0)+IF(ISNUMBER(SEARCH(MAP_TNHN!D11&" (2 tiết)",'PL10'!$S$6)),1,0)+IF(ISNUMBER(SEARCH(MAP_TNHN!D11&" (2 tiết)",'PL10'!$S$7)),1,0)+IF(ISNUMBER(SEARCH(MAP_TNHN!D11&" (2 tiết)",'PL10'!$S$8)),1,0)+IF(ISNUMBER(SEARCH(MAP_TNHN!D11&" (2 tiết)",'PL10'!$S$9)),1,0)+IF(ISNUMBER(SEARCH(MAP_TNHN!D11&" (2 tiết)",'PL10'!$S$10)),1,0)+IF(ISNUMBER(SEARCH(MAP_TNHN!D11&" (2 tiết)",'PL10'!$S$11)),1,0)+IF(ISNUMBER(SEARCH(MAP_TNHN!D11&" (2 tiết)",'PL10'!$S$12)),1,0)+IF(ISNUMBER(SEARCH(MAP_TNHN!D11&" (2 tiết)",'PL10'!$S$13)),1,0)+IF(ISNUMBER(SEARCH(MAP_TNHN!D11&" (2 tiết)",'PL10'!$S$14)),1,0)+IF(ISNUMBER(SEARCH(MAP_TNHN!D11&" (2 tiết)",'PL10'!$S$15)),1,0)+IF(ISNUMBER(SEARCH(MAP_TNHN!D11&" (2 tiết)",'PL10'!$S$16)),1,0)+IF(ISNUMBER(SEARCH(MAP_TNHN!D11&" (2 tiết)",'PL10'!$S$17)),1,0)+IF(ISNUMBER(SEARCH(MAP_TNHN!D11&" (2 tiết)",'PL10'!$S$18)),1,0)+IF(ISNUMBER(SEARCH(MAP_TNHN!D11&" (2 tiết)",'PL10'!$S$19)),1,0)+IF(ISNUMBER(SEARCH(MAP_TNHN!D11&" (2 tiết)",'PL10'!$S$20)),1,0)+IF(ISNUMBER(SEARCH(MAP_TNHN!D11&" (2 tiết)",'PL10'!$S$21)),1,0)+IF(ISNUMBER(SEARCH(MAP_TNHN!D11&" (2 tiết)",'PL10'!$S$22)),1,0)+IF(ISNUMBER(SEARCH(MAP_TNHN!D11&" (2 tiết)",'PL10'!$S$23)),1,0)+IF(ISNUMBER(SEARCH(MAP_TNHN!D11&" (2 tiết)",'PL10'!$S$24)),1,0)+IF(ISNUMBER(SEARCH(MAP_TNHN!D11&" (2 tiết)",'PL10'!$S$25)),1,0)))) -> 1
B12: 7 | C12: VĂN HUỲNH BẢO PHƯƠNG | K12: 3 | P12: 3 | Q12: 1 | U12: =E12*'Phân tiết'!$M$7+G12*('Phân tiết'!$M$21/3)+H12*'Phân tiết'!$L$26+AW12+J12*'Phân tiết'!$M$20+K12*'Phân tiết'!$I$7+M12*('Phân tiết'!$I$21/3)+AX12+O12*'Phân tiết'!$I$20+P12*'Phân tiết'!$E$7+R12*('Phân tiết'!$E$21/3)+AY12+T12*'Phân tiết'!$E$20 -> 18 | V12: =F12*4+L12*4+Q12*4 -> 4 | Z12: =SUM(U12:Y12) -> 22 | AA12: =Z12-17 -> 5 | AD12: =AB12*AC12*1.5 -> 0 | AG12: =AE12*AF12*1.5 -> 0 | AJ12: =AH12*AI12 -> 0 | AK12: =AA12*33+AD12+AG12+AJ12 -> 165 | AO12: X | AP12: X | AQ12: X | AR12: X | AT12: X | AV12: Nghỉ thai sản từ 01/4 - 01/10/2025 | AW12: =IF(I12="",0,IF(MAP_TNHN!B12="",I12*3,I12*3-2*(IF(ISNUMBER(SEARCH(MAP_TNHN!B12&" (1 tiết)",'PL12'!$S$5)),1,0)+IF(ISNUMBER(SEARCH(MAP_TNHN!B12&" (1 tiết)",'PL12'!$S$6)),1,0)+IF(ISNUMBER(SEARCH(MAP_TNHN!B12&" (1 tiết)",'PL12'!$S$7)),1,0)+IF(ISNUMBER(SEARCH(MAP_TNHN!B12&" (1 tiết)",'PL12'!$S$8)),1,0)+IF(ISNUMBER(SEARCH(MAP_TNHN!B12&" (1 tiết)",'PL12'!$S$9)),1,0)+IF(ISNUMBER(SEARCH(MAP_TNHN!B12&" (1 tiết)",'PL12'!$S$10)),1,0)+IF(ISNUMBER(SEARCH(MAP_TNHN!B12&" (1 tiết)",'PL12'!$S$11)),1,0)+IF(ISNUMBER(SEARCH(MAP_TNHN!B12&" (1 tiết)",'PL12'!$S$12)),1,0)+IF(ISNUMBER(SEARCH(MAP_TNHN!B12&" (1 tiết)",'PL12'!$S$13)),1,0)+IF(ISNUMBER(SEARCH(MAP_TNHN!B12&" (1 tiết)",'PL12'!$S$14)),1,0)+IF(ISNUMBER(SEARCH(MAP_TNHN!B12&" (1 tiết)",'PL12'!$S$15)),1,0)+IF(ISNUMBER(SEARCH(MAP_TNHN!B12&" (1 tiết)",'PL12'!$S$16)),1,0)+IF(ISNUMBER(SEARCH(MAP_TNHN!B12&" (1 tiết)",'PL12'!$S$17)),1,0)+IF(ISNUMBER(SEARCH(MAP_TNHN!B12&" (1 tiết)",'PL12'!$S$18)),1,0)+IF(ISNUMBER(SEARCH(MAP_TNHN!B12&" (1 tiết)",'PL12'!$S$19)),1,0))-(IF(ISNUMBER(SEARCH(MAP_TNHN!B12&" (2 tiết)",'PL12'!$S$5)),1,0)+IF(ISNUMBER(SEARCH(MAP_TNHN!B12&" (2 tiết)",'PL12'!$S$6)),1,0)+IF(ISNUMBER(SEARCH(MAP_TNHN!B12&" (2 tiết)",'PL12'!$S$7)),1,0)+IF(ISNUMBER(SEARCH(MAP_TNHN!B12&" (2 tiết)",'PL12'!$S$8)),1,0)+IF(ISNUMBER(SEARCH(MAP_TNHN!B12&" (2 tiết)",'PL12'!$S$9)),1,0)+IF(ISNUMBER(SEARCH(MAP_TNHN!B12&" (2 tiết)",'PL12'!$S$10)),1,0)+IF(ISNUMBER(SEARCH(MAP_TNHN!B12&" (2 tiết)",'PL12'!$S$11)),1,0)+IF(ISNUMBER(SEARCH(MAP_TNHN!B12&" (2 tiết)",'PL12'!$S$12)),1,0)+IF(ISNUMBER(SEARCH(MAP_TNHN!B12&" (2 tiết)",'PL12'!$S$13)),1,0)+IF(ISNUMBER(SEARCH(MAP_TNHN!B12&" (2 tiết)",'PL12'!$S$14)),1,0)+IF(ISNUMBER(SEARCH(MAP_TNHN!B12&" (2 tiết)",'PL12'!$S$15)),1,0)+IF(ISNUMBER(SEARCH(MAP_TNHN!B12&" (2 tiết)",'PL12'!$S$16)),1,0)+IF(ISNUMBER(SEARCH(MAP_TNHN!B12&" (2 tiết)",'PL12'!$S$17)),1,0)+IF(ISNUMBER(SEARCH(MAP_TNHN!B12&" (2 tiết)",'PL12'!$S$18)),1,0)+IF(ISNUMBER(SEARCH(MAP_TNHN!B12&" (2 tiết)",'PL12'!$S$19)),1,0)))) -> 0 | AX12: =IF(N12="",0,IF(MAP_TNHN!C12="",N12*3,N12*3-2*(IF(ISNUMBER(SEARCH(MAP_TNHN!C12&" (1 tiết)",'PL11'!$S$5)),1,0)+IF(ISNUMBER(SEARCH(MAP_TNHN!C12&" (1 tiết)",'PL11'!$S$6)),1,0)+IF(ISNUMBER(SEARCH(MAP_TNHN!C12&" (1 tiết)",'PL11'!$S$7)),1,0)+IF(ISNUMBER(SEARCH(MAP_TNHN!C12&" (1 tiết)",'PL11'!$S$8)),1,0)+IF(ISNUMBER(SEARCH(MAP_TNHN!C12&" (1 tiết)",'PL11'!$S$9)),1,0)+IF(ISNUMBER(SEARCH(MAP_TNHN!C12&" (1 tiết)",'PL11'!$S$10)),1,0)+IF(ISNUMBER(SEARCH(MAP_TNHN!C12&" (1 tiết)",'PL11'!$S$11)),1,0)+IF(ISNUMBER(SEARCH(MAP_TNHN!C12&" (1 tiết)",'PL11'!$S$12)),1,0)+IF(ISNUMBER(SEARCH(MAP_TNHN!C12&" (1 tiết)",'PL11'!$S$13)),1,0)+IF(ISNUMBER(SEARCH(MAP_TNHN!C12&" (1 tiết)",'PL11'!$S$14)),1,0)+IF(ISNUMBER(SEARCH(MAP_TNHN!C12&" (1 tiết)",'PL11'!$S$15)),1,0)+IF(ISNUMBER(SEARCH(MAP_TNHN!C12&" (1 tiết)",'PL11'!$S$16)),1,0)+IF(ISNUMBER(SEARCH(MAP_TNHN!C12&" (1 tiết)",'PL11'!$S$17)),1,0)+IF(ISNUMBER(SEARCH(MAP_TNHN!C12&" (1 tiết)",'PL11'!$S$18)),1,0))-(IF(ISNUMBER(SEARCH(MAP_TNHN!C12&" (2 tiết)",'PL11'!$S$5)),1,0)+IF(ISNUMBER(SEARCH(MAP_TNHN!C12&" (2 tiết)",'PL11'!$S$6)),1,0)+IF(ISNUMBER(SEARCH(MAP_TNHN!C12&" (2 tiết)",'PL11'!$S$7)),1,0)+IF(ISNUMBER(SEARCH(MAP_TNHN!C12&" (2 tiết)",'PL11'!$S$8)),1,0)+IF(ISNUMBER(SEARCH(MAP_TNHN!C12&" (2 tiết)",'PL11'!$S$9)),1,0)+IF(ISNUMBER(SEARCH(MAP_TNHN!C12&" (2 tiết)",'PL11'!$S$10)),1,0)+IF(ISNUMBER(SEARCH(MAP_TNHN!C12&" (2 tiết)",'PL11'!$S$11)),1,0)+IF(ISNUMBER(SEARCH(MAP_TNHN!C12&" (2 tiết)",'PL11'!$S$12)),1,0)+IF(ISNUMBER(SEARCH(MAP_TNHN!C12&" (2 tiết)",'PL11'!$S$13)),1,0)+IF(ISNUMBER(SEARCH(MAP_TNHN!C12&" (2 tiết)",'PL11'!$S$14)),1,0)+IF(ISNUMBER(SEARCH(MAP_TNHN!C12&" (2 tiết)",'PL11'!$S$15)),1,0)+IF(ISNUMBER(SEARCH(MAP_TNHN!C12&" (2 tiết)",'PL11'!$S$16)),1,0)+IF(ISNUMBER(SEARCH(MAP_TNHN!C12&" (2 tiết)",'PL11'!$S$17)),1,0)+IF(ISNUMBER(SEARCH(MAP_TNHN!C12&" (2 tiết)",'PL11'!$S$18)),1,0)))) -> 0 | AY12: =IF(S12="",0,IF(MAP_TNHN!D12="",S12*3,S12*3-2*(IF(ISNUMBER(SEARCH(MAP_TNHN!D12&" (1 tiết)",'PL10'!$S$5)),1,0)+IF(ISNUMBER(SEARCH(MAP_TNHN!D12&" (1 tiết)",'PL10'!$S$6)),1,0)+IF(ISNUMBER(SEARCH(MAP_TNHN!D12&" (1 tiết)",'PL10'!$S$7)),1,0)+IF(ISNUMBER(SEARCH(MAP_TNHN!D12&" (1 tiết)",'PL10'!$S$8)),1,0)+IF(ISNUMBER(SEARCH(MAP_TNHN!D12&" (1 tiết)",'PL10'!$S$9)),1,0)+IF(ISNUMBER(SEARCH(MAP_TNHN!D12&" (1 tiết)",'PL10'!$S$10)),1,0)+IF(ISNUMBER(SEARCH(MAP_TNHN!D12&" (1 tiết)",'PL10'!$S$11)),1,0)+IF(ISNUMBER(SEARCH(MAP_TNHN!D12&" (1 tiết)",'PL10'!$S$12)),1,0)+IF(ISNUMBER(SEARCH(MAP_TNHN!D12&" (1 tiết)",'PL10'!$S$13)),1,0)+IF(ISNUMBER(SEARCH(MAP_TNHN!D12&" (1 tiết)",'PL10'!$S$14)),1,0)+IF(ISNUMBER(SEARCH(MAP_TNHN!D12&" (1 tiết)",'PL10'!$S$15)),1,0)+IF(ISNUMBER(SEARCH(MAP_TNHN!D12&" (1 tiết)",'PL10'!$S$16)),1,0)+IF(ISNUMBER(SEARCH(MAP_TNHN!D12&" (1 tiết)",'PL10'!$S$17)),1,0)+IF(ISNUMBER(SEARCH(MAP_TNHN!D12&" (1 tiết)",'PL10'!$S$18)),1,0)+IF(ISNUMBER(SEARCH(MAP_TNHN!D12&" (1 tiết)",'PL10'!$S$19)),1,0)+IF(ISNUMBER(SEARCH(MAP_TNHN!D12&" (1 tiết)",'PL10'!$S$20)),1,0)+IF(ISNUMBER(SEARCH(MAP_TNHN!D12&" (1 tiết)",'PL10'!$S$21)),1,0)+IF(ISNUMBER(SEARCH(MAP_TNHN!D12&" (1 tiết)",'PL10'!$S$22)),1,0)+IF(ISNUMBER(SEARCH(MAP_TNHN!D12&" (1 tiết)",'PL10'!$S$23)),1,0)+IF(ISNUMBER(SEARCH(MAP_TNHN!D12&" (1 tiết)",'PL10'!$S$24)),1,0)+IF(ISNUMBER(SEARCH(MAP_TNHN!D12&" (1 tiết)",'PL10'!$S$25)),1,0))-(IF(ISNUMBER(SEARCH(MAP_TNHN!D12&" (2 tiết)",'PL10'!$S$5)),1,0)+IF(ISNUMBER(SEARCH(MAP_TNHN!D12&" (2 tiết)",'PL10'!$S$6)),1,0)+IF(ISNUMBER(SEARCH(MAP_TNHN!D12&" (2 tiết)",'PL10'!$S$7)),1,0)+IF(ISNUMBER(SEARCH(MAP_TNHN!D12&" (2 tiết)",'PL10'!$S$8)),1,0)+IF(ISNUMBER(SEARCH(MAP_TNHN!D12&" (2 tiết)",'PL10'!$S$9)),1,0)+IF(ISNUMBER(SEARCH(MAP_TNHN!D12&" (2 tiết)",'PL10'!$S$10)),1,0)+IF(ISNUMBER(SEARCH(MAP_TNHN!D12&" (2 tiết)",'PL10'!$S$11)),1,0)+IF(ISNUMBER(SEARCH(MAP_TNHN!D12&" (2 tiết)",'PL10'!$S$12)),1,0)+IF(ISNUMBER(SEARCH(MAP_TNHN!D12&" (2 tiết)",'PL10'!$S$13)),1,0)+IF(ISNUMBER(SEARCH(MAP_TNHN!D12&" (2 tiết)",'PL10'!$S$14)),1,0)+IF(ISNUMBER(SEARCH(MAP_TNHN!D12&" (2 tiết)",'PL10'!$S$15)),1,0)+IF(ISNUMBER(SEARCH(MAP_TNHN!D12&" (2 tiết)",'PL10'!$S$16)),1,0)+IF(ISNUMBER(SEARCH(MAP_TNHN!D12&" (2 tiết)",'PL10'!$S$17)),1,0)+IF(ISNUMBER(SEARCH(MAP_TNHN!D12&" (2 tiết)",'PL10'!$S$18)),1,0)+IF(ISNUMBER(SEARCH(MAP_TNHN!D12&" (2 tiết)",'PL10'!$S$19)),1,0)+IF(ISNUMBER(SEARCH(MAP_TNHN!D12&" (2 tiết)",'PL10'!$S$20)),1,0)+IF(ISNUMBER(SEARCH(MAP_TNHN!D12&" (2 tiết)",'PL10'!$S$21)),1,0)+IF(ISNUMBER(SEARCH(MAP_TNHN!D12&" (2 tiết)",'PL10'!$S$22)),1,0)+IF(ISNUMBER(SEARCH(MAP_TNHN!D12&" (2 tiết)",'PL10'!$S$23)),1,0)+IF(ISNUMBER(SEARCH(MAP_TNHN!D12&" (2 tiết)",'PL10'!$S$24)),1,0)+IF(ISNUMBER(SEARCH(MAP_TNHN!D12&" (2 tiết)",'PL10'!$S$25)),1,0)))) -> 0
B13: 8 | C13: TRẦN THỊ MỸ THANH | D13: 12 | E13: 2 | F13: 1 | H13: 2 | K13: 3 | U13: =E13*'Phân tiết'!$M$7+G13*('Phân tiết'!$M$21/3)+H13*'Phân tiết'!$L$26+AW13+J13*'Phân tiết'!$M$20+K13*'Phân tiết'!$I$7+M13*('Phân tiết'!$I$21/3)+AX13+O13*'Phân tiết'!$I$20+P13*'Phân tiết'!$E$7+R13*('Phân tiết'!$E$21/3)+AY13+T13*'Phân tiết'!$E$20 -> 19 | V13: =F13*4+L13*4+Q13*4 -> 4 | Z13: =SUM(U13:Y13) -> 23 | AA13: =Z13-17 -> 6 | AD13: =AB13*AC13*1.5 -> 0 | AG13: =AE13*AF13*1.5 -> 0 | AJ13: =AH13*AI13 -> 0 | AK13: =AA13*33+AD13+AG13+AJ13 -> 198 | AN13: X | AO13: X | AP13: X | AQ13: X | AR13: X | AT13: X | AW13: =IF(I13="",0,IF(MAP_TNHN!B13="",I13*3,I13*3-2*(IF(ISNUMBER(SEARCH(MAP_TNHN!B13&" (1 tiết)",'PL12'!$S$5)),1,0)+IF(ISNUMBER(SEARCH(MAP_TNHN!B13&" (1 tiết)",'PL12'!$S$6)),1,0)+IF(ISNUMBER(SEARCH(MAP_TNHN!B13&" (1 tiết)",'PL12'!$S$7)),1,0)+IF(ISNUMBER(SEARCH(MAP_TNHN!B13&" (1 tiết)",'PL12'!$S$8)),1,0)+IF(ISNUMBER(SEARCH(MAP_TNHN!B13&" (1 tiết)",'PL12'!$S$9)),1,0)+IF(ISNUMBER(SEARCH(MAP_TNHN!B13&" (1 tiết)",'PL12'!$S$10)),1,0)+IF(ISNUMBER(SEARCH(MAP_TNHN!B13&" (1 tiết)",'PL12'!$S$11)),1,0)+IF(ISNUMBER(SEARCH(MAP_TNHN!B13&" (1 tiết)",'PL12'!$S$12)),1,0)+IF(ISNUMBER(SEARCH(MAP_TNHN!B13&" (1 tiết)",'PL12'!$S$13)),1,0)+IF(ISNUMBER(SEARCH(MAP_TNHN!B13&" (1 tiết)",'PL12'!$S$14)),1,0)+IF(ISNUMBER(SEARCH(MAP_TNHN!B13&" (1 tiết)",'PL12'!$S$15)),1,0)+IF(ISNUMBER(SEARCH(MAP_TNHN!B13&" (1 tiết)",'PL12'!$S$16)),1,0)+IF(ISNUMBER(SEARCH(MAP_TNHN!B13&" (1 tiết)",'PL12'!$S$17)),1,0)+IF(ISNUMBER(SEARCH(MAP_TNHN!B13&" (1 tiết)",'PL12'!$S$18)),1,0)+IF(ISNUMBER(SEARCH(MAP_TNHN!B13&" (1 tiết)",'PL12'!$S$19)),1,0))-(IF(ISNUMBER(SEARCH(MAP_TNHN!B13&" (2 tiết)",'PL12'!$S$5)),1,0)+IF(ISNUMBER(SEARCH(MAP_TNHN!B13&" (2 tiết)",'PL12'!$S$6)),1,0)+IF(ISNUMBER(SEARCH(MAP_TNHN!B13&" (2 tiết)",'PL12'!$S$7)),1,0)+IF(ISNUMBER(SEARCH(MAP_TNHN!B13&" (2 tiết)",'PL12'!$S$8)),1,0)+IF(ISNUMBER(SEARCH(MAP_TNHN!B13&" (2 tiết)",'PL12'!$S$9)),1,0)+IF(ISNUMBER(SEARCH(MAP_TNHN!B13&" (2 tiết)",'PL12'!$S$10)),1,0)+IF(ISNUMBER(SEARCH(MAP_TNHN!B13&" (2 tiết)",'PL12'!$S$11)),1,0)+IF(ISNUMBER(SEARCH(MAP_TNHN!B13&" (2 tiết)",'PL12'!$S$12)),1,0)+IF(ISNUMBER(SEARCH(MAP_TNHN!B13&" (2 tiết)",'PL12'!$S$13)),1,0)+IF(ISNUMBER(SEARCH(MAP_TNHN!B13&" (2 tiết)",'PL12'!$S$14)),1,0)+IF(ISNUMBER(SEARCH(MAP_TNHN!B13&" (2 tiết)",'PL12'!$S$15)),1,0)+IF(ISNUMBER(SEARCH(MAP_TNHN!B13&" (2 tiết)",'PL12'!$S$16)),1,0)+IF(ISNUMBER(SEARCH(MAP_TNHN!B13&" (2 tiết)",'PL12'!$S$17)),1,0)+IF(ISNUMBER(SEARCH(MAP_TNHN!B13&" (2 tiết)",'PL12'!$S$18)),1,0)+IF(ISNUMBER(SEARCH(MAP_TNHN!B13&" (2 tiết)",'PL12'!$S$19)),1,0)))) -> 0 | AX13: =IF(N13="",0,IF(MAP_TNHN!C13="",N13*3,N13*3-2*(IF(ISNUMBER(SEARCH(MAP_TNHN!C13&" (1 tiết)",'PL11'!$S$5)),1,0)+IF(ISNUMBER(SEARCH(MAP_TNHN!C13&" (1 tiết)",'PL11'!$S$6)),1,0)+IF(ISNUMBER(SEARCH(MAP_TNHN!C13&" (1 tiết)",'PL11'!$S$7)),1,0)+IF(ISNUMBER(SEARCH(MAP_TNHN!C13&" (1 tiết)",'PL11'!$S$8)),1,0)+IF(ISNUMBER(SEARCH(MAP_TNHN!C13&" (1 tiết)",'PL11'!$S$9)),1,0)+IF(ISNUMBER(SEARCH(MAP_TNHN!C13&" (1 tiết)",'PL11'!$S$10)),1,0)+IF(ISNUMBER(SEARCH(MAP_TNHN!C13&" (1 tiết)",'PL11'!$S$11)),1,0)+IF(ISNUMBER(SEARCH(MAP_TNHN!C13&" (1 tiết)",'PL11'!$S$12)),1,0)+IF(ISNUMBER(SEARCH(MAP_TNHN!C13&" (1 tiết)",'PL11'!$S$13)),1,0)+IF(ISNUMBER(SEARCH(MAP_TNHN!C13&" (1 tiết)",'PL11'!$S$14)),1,0)+IF(ISNUMBER(SEARCH(MAP_TNHN!C13&" (1 tiết)",'PL11'!$S$15)),1,0)+IF(ISNUMBER(SEARCH(MAP_TNHN!C13&" (1 tiết)",'PL11'!$S$16)),1,0)+IF(ISNUMBER(SEARCH(MAP_TNHN!C13&" (1 tiết)",'PL11'!$S$17)),1,0)+IF(ISNUMBER(SEARCH(MAP_TNHN!C13&" (1 tiết)",'PL11'!$S$18)),1,0))-(IF(ISNUMBER(SEARCH(MAP_TNHN!C13&" (2 tiết)",'PL11'!$S$5)),1,0)+IF(ISNUMBER(SEARCH(MAP_TNHN!C13&" (2 tiết)",'PL11'!$S$6)),1,0)+IF(ISNUMBER(SEARCH(MAP_TNHN!C13&" (2 tiết)",'PL11'!$S$7)),1,0)+IF(ISNUMBER(SEARCH(MAP_TNHN!C13&" (2 tiết)",'PL11'!$S$8)),1,0)+IF(ISNUMBER(SEARCH(MAP_TNHN!C13&" (2 tiết)",'PL11'!$S$9)),1,0)+IF(ISNUMBER(SEARCH(MAP_TNHN!C13&" (2 tiết)",'PL11'!$S$10)),1,0)+IF(ISNUMBER(SEARCH(MAP_TNHN!C13&" (2 tiết)",'PL11'!$S$11)),1,0)+IF(ISNUMBER(SEARCH(MAP_TNHN!C13&" (2 tiết)",'PL11'!$S$12)),1,0)+IF(ISNUMBER(SEARCH(MAP_TNHN!C13&" (2 tiết)",'PL11'!$S$13)),1,0)+IF(ISNUMBER(SEARCH(MAP_TNHN!C13&" (2 tiết)",'PL11'!$S$14)),1,0)+IF(ISNUMBER(SEARCH(MAP_TNHN!C13&" (2 tiết)",'PL11'!$S$15)),1,0)+IF(ISNUMBER(SEARCH(MAP_TNHN!C13&" (2 tiết)",'PL11'!$S$16)),1,0)+IF(ISNUMBER(SEARCH(MAP_TNHN!C13&" (2 tiết)",'PL11'!$S$17)),1,0)+IF(ISNUMBER(SEARCH(MAP_TNHN!C13&" (2 tiết)",'PL11'!$S$18)),1,0)))) -> 0 | AY13: =IF(S13="",0,IF(MAP_TNHN!D13="",S13*3,S13*3-2*(IF(ISNUMBER(SEARCH(MAP_TNHN!D13&" (1 tiết)",'PL10'!$S$5)),1,0)+IF(ISNUMBER(SEARCH(MAP_TNHN!D13&" (1 tiết)",'PL10'!$S$6)),1,0)+IF(ISNUMBER(SEARCH(MAP_TNHN!D13&" (1 tiết)",'PL10'!$S$7)),1,0)+IF(ISNUMBER(SEARCH(MAP_TNHN!D13&" (1 tiết)",'PL10'!$S$8)),1,0)+IF(ISNUMBER(SEARCH(MAP_TNHN!D13&" (1 tiết)",'PL10'!$S$9)),1,0)+IF(ISNUMBER(SEARCH(MAP_TNHN!D13&" (1 tiết)",'PL10'!$S$10)),1,0)+IF(ISNUMBER(SEARCH(MAP_TNHN!D13&" (1 tiết)",'PL10'!$S$11)),1,0)+IF(ISNUMBER(SEARCH(MAP_TNHN!D13&" (1 tiết)",'PL10'!$S$12)),1,0)+IF(ISNUMBER(SEARCH(MAP_TNHN!D13&" (1 tiết)",'PL10'!$S$13)),1,0)+IF(ISNUMBER(SEARCH(MAP_TNHN!D13&" (1 tiết)",'PL10'!$S$14)),1,0)+IF(ISNUMBER(SEARCH(MAP_TNHN!D13&" (1 tiết)",'PL10'!$S$15)),1,0)+IF(ISNUMBER(SEARCH(MAP_TNHN!D13&" (1 tiết)",'PL10'!$S$16)),1,0)+IF(ISNUMBER(SEARCH(MAP_TNHN!D13&" (1 tiết)",'PL10'!$S$17)),1,0)+IF(ISNUMBER(SEARCH(MAP_TNHN!D13&" (1 tiết)",'PL10'!$S$18)),1,0)+IF(ISNUMBER(SEARCH(MAP_TNHN!D13&" (1 tiết)",'PL10'!$S$19)),1,0)+IF(ISNUMBER(SEARCH(MAP_TNHN!D13&" (1 tiết)",'PL10'!$S$20)),1,0)+IF(ISNUMBER(SEARCH(MAP_TNHN!D13&" (1 tiết)",'PL10'!$S$21)),1,0)+IF(ISNUMBER(SEARCH(MAP_TNHN!D13&" (1 tiết)",'PL10'!$S$22)),1,0)+IF(ISNUMBER(SEARCH(MAP_TNHN!D13&" (1 tiết)",'PL10'!$S$23)),1,0)+IF(ISNUMBER(SEARCH(MAP_TNHN!D13&" (1 tiết)",'PL10'!$S$24)),1,0)+IF(ISNUMBER(SEARCH(MAP_TNHN!D13&" (1 tiết)",'PL10'!$S$25)),1,0))-(IF(ISNUMBER(SEARCH(MAP_TNHN!D13&" (2 tiết)",'PL10'!$S$5)),1,0)+IF(ISNUMBER(SEARCH(MAP_TNHN!D13&" (2 tiết)",'PL10'!$S$6)),1,0)+IF(ISNUMBER(SEARCH(MAP_TNHN!D13&" (2 tiết)",'PL10'!$S$7)),1,0)+IF(ISNUMBER(SEARCH(MAP_TNHN!D13&" (2 tiết)",'PL10'!$S$8)),1,0)+IF(ISNUMBER(SEARCH(MAP_TNHN!D13&" (2 tiết)",'PL10'!$S$9)),1,0)+IF(ISNUMBER(SEARCH(MAP_TNHN!D13&" (2 tiết)",'PL10'!$S$10)),1,0)+IF(ISNUMBER(SEARCH(MAP_TNHN!D13&" (2 tiết)",'PL10'!$S$11)),1,0)+IF(ISNUMBER(SEARCH(MAP_TNHN!D13&" (2 tiết)",'PL10'!$S$12)),1,0)+IF(ISNUMBER(SEARCH(MAP_TNHN!D13&" (2 tiết)",'PL10'!$S$13)),1,0)+IF(ISNUMBER(SEARCH(MAP_TNHN!D13&" (2 tiết)",'PL10'!$S$14)),1,0)+IF(ISNUMBER(SEARCH(MAP_TNHN!D13&" (2 tiết)",'PL10'!$S$15)),1,0)+IF(ISNUMBER(SEARCH(MAP_TNHN!D13&" (2 tiết)",'PL10'!$S$16)),1,0)+IF(ISNUMBER(SEARCH(MAP_TNHN!D13&" (2 tiết)",'PL10'!$S$17)),1,0)+IF(ISNUMBER(SEARCH(MAP_TNHN!D13&" (2 tiết)",'PL10'!$S$18)),1,0)+IF(ISNUMBER(SEARCH(MAP_TNHN!D13&" (2 tiết)",'PL10'!$S$19)),1,0)+IF(ISNUMBER(SEARCH(MAP_TNHN!D13&" (2 tiết)",'PL10'!$S$20)),1,0)+IF(ISNUMBER(SEARCH(MAP_TNHN!D13&" (2 tiết)",'PL10'!$S$21)),1,0)+IF(ISNUMBER(SEARCH(MAP_TNHN!D13&" (2 tiết)",'PL10'!$S$22)),1,0)+IF(ISNUMBER(SEARCH(MAP_TNHN!D13&" (2 tiết)",'PL10'!$S$23)),1,0)+IF(ISNUMBER(SEARCH(MAP_TNHN!D13&" (2 tiết)",'PL10'!$S$24)),1,0)+IF(ISNUMBER(SEARCH(MAP_TNHN!D13&" (2 tiết)",'PL10'!$S$25)),1,0)))) -> 0
